Workbook

Sheet Uitleg
B2: Jaarrapportage uren — Top Tuinen
B4: Wat is dit — Het jaaroverzicht van alle geregistreerde uren: per klant, per medewerker en per segment, met de verdeling factureerbaar versus intern. Dit is een rapportage — géén werkdocument. Facturen en statussen blijven in de maandelijkse facturatiesheet en HERO.
B6: Zo werkt het
B7: Data — Eén platte tabel met alle registraties van het jaar (ruimte voor 25.000 regels): datum, medewerker, klant, segment, omschrijving, van, tot en uren. Alleen waarden, geen formules — daardoor blijft het snel, ook bij een volledig jaar met 15 man. De uren-kolom is verplicht en moet een getal zijn (de app levert die mee).
B8: Dashboard — Kies bovenaan het jaar. Daaronder: jaartotalen, de verdeling factureerbaar / pauze / reistijd / laden+lossen / overig, het verloop per maand en de vier controles.
B9: Klant x maand — Facturabele uren per klant per maand, met jaartotaal. Vul (eenmalig) het uurtarief in voor een omzet-indicatie — die geldt alleen voor uurklanten; vaste-prijsomzet staat in HERO.
B10: Medewerker x maand — Totaal geregistreerde uren per medewerker per maand, plus per jaar: factureerbaar, reistijd en het percentage factureerbaar.
B11: Segmenten — Uren per segment per maand — hier zie je in één blik waar de niet-factureerbare tijd zit.
B13: Waar moet je kijken
B14: Dashboard, blok CONTROLES — Vier regels die allemaal groen moeten zijn: (1) bereik — geen data onder rij 25.001, (2) jaar — geen registraties buiten het gekozen jaar, (3) klantdekking — alle facturabele uren vallen onder een klant in de klantmatrix, (4) medewerkerdekking — alle uren vallen onder een medewerker in de matrix. Eén rode regel = het rapport is niet compleet en de melding zegt wat er mist.
B16: Spelregels
B17: Segmenten — Werken, Pauze, Reistijd, Laden, Lossen, Teammeeting, Onderhoud materiaal, Anders. Alleen "Werken" telt als factureerbaar.
... B19: Blauw/zwart — Blauwe cellen zijn invoer (jaar, klantenlijst, tarieven, medewerkerlijst). Zwart = formule, vergrendeld zonder wachtwoord.

Sheet Data
A1: Datum | B1: Medewerker | C1: Klant | D1: Segment | E1: Omschrijving | F1: Van | G1: Tot | H1: Uren

Sheet Dashboard
A1: Jaarrapportage — Top Tuinen
A2: Jaar: | B2: 2026
A4: JAARTOTALEN
B5: Totaal uren | D5: Factureerbaar (Werken) | F5: Pauze | H5: Reistijd | J5: Laden + Lossen | L5: Overig intern | N5: % factureerbaar
B6: =SUMIFS(Data!$H$2:$H$25001,Data!$A$2:$A$25001,">="&DATE(Dashboard!$B$2,1,1)&"",Data!$A$2:$A$25001,"<"&DATE(Dashboard!$B$2+1,1,1)&"") | D6: =SUMIFS(Data!$H$2:$H$25001,Data!$D$2:$D$25001,"Werken",Data!$A$2:$A$25001,">="&DATE(Dashboard!$B$2,1,1)&"",Data!$A$2:$A$25001,"<"&DATE(Dashboard!$B$2+1,1,1)&"") | F6: =SUMIFS(Data!$H$2:$H$25001,Data!$D$2:$D$25001,"Pauze",Data!$A$2:$A$25001,">="&DATE(Dashboard!$B$2,1,1)&"",Data!$A$2:$A$25001,"<"&DATE(Dashboard!$B$2+1,1,1)&"") | H6: =SUMIFS(Data!$H$2:$H$25001,Data!$D$2:$D$25001,"Reistijd",Data!$A$2:$A$25001,">="&DATE(Dashboard!$B$2,1,1)&"",Data!$A$2:$A$25001,"<"&DATE(Dashboard!$B$2+1,1,1)&"") | J6: =SUMIFS(Data!$H$2:$H$25001,Data!$D$2:$D$25001,"Laden",Data!$A$2:$A$25001,">="&DATE(Dashboard!$B$2,1,1)&"",Data!$A$2:$A$25001,"<"&DATE(Dashboard!$B$2+1,1,1)&"")+SUMIFS(Data!$H$2:$H$25001,Data!$D$2:$D$25001,"Lossen",Data!$A$2:$A$25001,">="&DATE(Dashboard!$B$2,1,1)&"",Data!$A$2:$A$25001,"<"&DATE(Dashboard!$B$2+1,1,1)&"") | L6: =B6-D6-F6-H6-J6 | N6: =IF(B6=0,"",D6/B6)
A9: PER MAAND
B10: jan | C10: feb | D10: mrt | E10: apr | F10: mei | G10: jun | H10: jul | I10: aug | J10: sep | K10: okt | L10: nov | M10: dec | N10: Jaar
A11: Totaal uren | B11: =SUMIFS(Data!$H$2:$H$25001,Data!$A$2:$A$25001,">="&DATE(Dashboard!$B$2,1,1)&"",Data!$A$2:$A$25001,"<"&DATE(Dashboard!$B$2,1+1,1)&"") | C11: =SUMIFS(Data!$H$2:$H$25001,Data!$A$2:$A$25001,">="&DATE(Dashboard!$B$2,2,1)&"",Data!$A$2:$A$25001,"<"&DATE(Dashboard!$B$2,2+1,1)&"") | D11: =SUMIFS(Data!$H$2:$H$25001,Data!$A$2:$A$25001,">="&DATE(Dashboard!$B$2,3,1)&"",Data!$A$2:$A$25001,"<"&DATE(Dashboard!$B$2,3+1,1)&"") | E11: =SUMIFS(Data!$H$2:$H$25001,Data!$A$2:$A$25001,">="&DATE(Dashboard!$B$2,4,1)&"",Data!$A$2:$A$25001,"<"&DATE(Dashboard!$B$2,4+1,1)&"") | F11: =SUMIFS(Data!$H$2:$H$25001,Data!$A$2:$A$25001,">="&DATE(Dashboard!$B$2,5,1)&"",Data!$A$2:$A$25001,"<"&DATE(Dashboard!$B$2,5+1,1)&"") | G11: =SUMIFS(Data!$H$2:$H$25001,Data!$A$2:$A$25001,">="&DATE(Dashboard!$B$2,6,1)&"",Data!$A$2:$A$25001,"<"&DATE(Dashboard!$B$2,6+1,1)&"") | H11: =SUMIFS(Data!$H$2:$H$25001,Data!$A$2:$A$25001,">="&DATE(Dashboard!$B$2,7,1)&"",Data!$A$2:$A$25001,"<"&DATE(Dashboard!$B$2,7+1,1)&"") | I11: =SUMIFS(Data!$H$2:$H$25001,Data!$A$2:$A$25001,">="&DATE(Dashboard!$B$2,8,1)&"",Data!$A$2:$A$25001,"<"&DATE(Dashboard!$B$2,8+1,1)&"") | J11: =SUMIFS(Data!$H$2:$H$25001,Data!$A$2:$A$25001,">="&DATE(Dashboard!$B$2,9,1)&"",Data!$A$2:$A$25001,"<"&DATE(Dashboard!$B$2,9+1,1)&"") | K11: =SUMIFS(Data!$H$2:$H$25001,Data!$A$2:$A$25001,">="&DATE(Dashboard!$B$2,10,1)&"",Data!$A$2:$A$25001,"<"&DATE(Dashboard!$B$2,10+1,1)&"") | L11: =SUMIFS(Data!$H$2:$H$25001,Data!$A$2:$A$25001,">="&DATE(Dashboard!$B$2,11,1)&"",Data!$A$2:$A$25001,"<"&DATE(Dashboard!$B$2,11+1,1)&"") | M11: =SUMIFS(Data!$H$2:$H$25001,Data!$A$2:$A$25001,">="&DATE(Dashboard!$B$2,12,1)&"",Data!$A$2:$A$25001,"<"&DATE(Dashboard!$B$2,12+1,1)&"") | N11: =SUM(B11:M11)
A12: Factureerbaar | B12: =SUMIFS(Data!$H$2:$H$25001,Data!$D$2:$D$25001,"Werken",Data!$A$2:$A$25001,">="&DATE(Dashboard!$B$2,1,1)&"",Data!$A$2:$A$25001,"<"&DATE(Dashboard!$B$2,1+1,1)&"") | C12: =SUMIFS(Data!$H$2:$H$25001,Data!$D$2:$D$25001,"Werken",Data!$A$2:$A$25001,">="&DATE(Dashboard!$B$2,2,1)&"",Data!$A$2:$A$25001,"<"&DATE(Dashboard!$B$2,2+1,1)&"") | D12: =SUMIFS(Data!$H$2:$H$25001,Data!$D$2:$D$25001,"Werken",Data!$A$2:$A$25001,">="&DATE(Dashboard!$B$2,3,1)&"",Data!$A$2:$A$25001,"<"&DATE(Dashboard!$B$2,3+1,1)&"") | E12: =SUMIFS(Data!$H$2:$H$25001,Data!$D$2:$D$25001,"Werken",Data!$A$2:$A$25001,">="&DATE(Dashboard!$B$2,4,1)&"",Data!$A$2:$A$25001,"<"&DATE(Dashboard!$B$2,4+1,1)&"") | F12: =SUMIFS(Data!$H$2:$H$25001,Data!$D$2:$D$25001,"Werken",Data!$A$2:$A$25001,">="&DATE(Dashboard!$B$2,5,1)&"",Data!$A$2:$A$25001,"<"&DATE(Dashboard!$B$2,5+1,1)&"") | G12: =SUMIFS(Data!$H$2:$H$25001,Data!$D$2:$D$25001,"Werken",Data!$A$2:$A$25001,">="&DATE(Dashboard!$B$2,6,1)&"",Data!$A$2:$A$25001,"<"&DATE(Dashboard!$B$2,6+1,1)&"") | H12: =SUMIFS(Data!$H$2:$H$25001,Data!$D$2:$D$25001,"Werken",Data!$A$2:$A$25001,">="&DATE(Dashboard!$B$2,7,1)&"",Data!$A$2:$A$25001,"<"&DATE(Dashboard!$B$2,7+1,1)&"") | I12: =SUMIFS(Data!$H$2:$H$25001,Data!$D$2:$D$25001,"Werken",Data!$A$2:$A$25001,">="&DATE(Dashboard!$B$2,8,1)&"",Data!$A$2:$A$25001,"<"&DATE(Dashboard!$B$2,8+1,1)&"") | J12: =SUMIFS(Data!$H$2:$H$25001,Data!$D$2:$D$25001,"Werken",Data!$A$2:$A$25001,">="&DATE(Dashboard!$B$2,9,1)&"",Data!$A$2:$A$25001,"<"&DATE(Dashboard!$B$2,9+1,1)&"") | K12: =SUMIFS(Data!$H$2:$H$25001,Data!$D$2:$D$25001,"Werken",Data!$A$2:$A$25001,">="&DATE(Dashboard!$B$2,10,1)&"",Data!$A$2:$A$25001,"<"&DATE(Dashboard!$B$2,10+1,1)&"") | L12: =SUMIFS(Data!$H$2:$H$25001,Data!$D$2:$D$25001,"Werken",Data!$A$2:$A$25001,">="&DATE(Dashboard!$B$2,11,1)&"",Data!$A$2:$A$25001,"<"&DATE(Dashboard!$B$2,11+1,1)&"") | M12: =SUMIFS(Data!$H$2:$H$25001,Data!$D$2:$D$25001,"Werken",Data!$A$2:$A$25001,">="&DATE(Dashboard!$B$2,12,1)&"",Data!$A$2:$A$25001,"<"&DATE(Dashboard!$B$2,12+1,1)&"") | N12: =SUM(B12:M12)
A13: Intern | B13: =B11-B12 | C13: =C11-C12 | D13: =D11-D12 | E13: =E11-E12 | F13: =F11-F12 | G13: =G11-G12 | H13: =H11-H12 | I13: =I11-I12 | ... M13: =M11-M12 | N13: =SUM(B13:M13)
A16: CONTROLES
A17: =IF(COUNTA(Data!A25002:A40000)+COUNTA(Data!D25002:D40000)=0,"OK - alle data binnen bereik (t/m rij 25001)","LET OP: data onder rij 25001 telt NIET mee")
A18: =IF(SUMPRODUCT((Data!A2:A25001<>"")*1)-COUNTIFS(Data!$A$2:$A$25001,">="&DATE(Dashboard!$B$2,1,1)&"",Data!$A$2:$A$25001,"<"&DATE(Dashboard!$B$2+1,1,1)&"")=0,"OK - alle registraties vallen in "&Dashboard!$B$2,"LET OP: "&(SUMPRODUCT((Data!A2:A25001<>"")*1)-COUNTIFS(Data!$A$2:$A$25001,">="&DATE(Dashboard!$B$2,1,1)&"",Data!$A$2:$A$25001,"<"&DATE(Dashboard!$B$2+1,1,1)&""))&" registratie(s) buiten "&Dashboard!$B$2)
A19: =IF(ROUND(SUMIFS(Data!$H$2:$H$25001,Data!$D$2:$D$25001,"Werken",Data!$A$2:$A$25001,">="&DATE(Dashboard!$B$2,1,1)&"",Data!$A$2:$A$25001,"<"&DATE(Dashboard!$B$2+1,1,1)&"")-SUM('Klant x maand'!N7:N156),2)=0,"OK - alle facturabele uren vallen onder een klant in de klantmatrix","LET OP: "&TEXT(SUMIFS(Data!$H$2:$H$25001,Data!$D$2:$D$25001,"Werken",Data!$A$2:$A$25001,">="&DATE(Dashboard!$B$2,1,1)&"",Data!$A$2:$A$25001,"<"&DATE(Dashboard!$B$2+1,1,1)&"")-SUM('Klant x maand'!N7:N156),"0,00")&" facturabele uren zonder klant in de matrix")
A20: =IF(ROUND(SUMIFS(Data!$H$2:$H$25001,Data!$A$2:$A$25001,">="&DATE(Dashboard!$B$2,1,1)&"",Data!$A$2:$A$25001,"<"&DATE(Dashboard!$B$2+1,1,1)&"")-SUM('Medewerker x maand'!N7:N31),2)=0,"OK - alle uren vallen onder een medewerker in de matrix","LET OP: "&TEXT(SUMIFS(Data!$H$2:$H$25001,Data!$A$2:$A$25001,">="&DATE(Dashboard!$B$2,1,1)&"",Data!$A$2:$A$25001,"<"&DATE(Dashboard!$B$2+1,1,1)&"")-SUM('Medewerker x maand'!N7:N31),"0,00")&" uren zonder medewerker in de matrix")

Sheet Klant x maand
A1: Facturabele uren per klant per maand
A2: Alleen segment "Werken". Klantnamen exact zoals in de app. Uurtarief invullen = omzet-indicatie (alleen uurklanten).
A6: Klant | B6: jan | C6: feb | D6: mrt | E6: apr | F6: mei | G6: jun | H6: jul | I6: aug | J6: sep | K6: okt | L6: nov | M6: dec | N6: Jaar | O6: Uurtarief | P6: Omzet-indicatie
B7: =IF($A7="","",SUMIFS(Data!$H$2:$H$25001,Data!$C$2:$C$25001,$A7,Data!$D$2:$D$25001,"Werken",Data!$A$2:$A$25001,">="&DATE(Dashboard!$B$2,1,1)&"",Data!$A$2:$A$25001,"<"&DATE(Dashboard!$B$2,1+1,1)&"")) | C7: =IF($A7="","",SUMIFS(Data!$H$2:$H$25001,Data!$C$2:$C$25001,$A7,Data!$D$2:$D$25001,"Werken",Data!$A$2:$A$25001,">="&DATE(Dashboard!$B$2,2,1)&"",Data!$A$2:$A$25001,"<"&DATE(Dashboard!$B$2,2+1,1)&"")) | D7: =IF($A7="","",SUMIFS(Data!$H$2:$H$25001,Data!$C$2:$C$25001,$A7,Data!$D$2:$D$25001,"Werken",Data!$A$2:$A$25001,">="&DATE(Dashboard!$B$2,3,1)&"",Data!$A$2:$A$25001,"<"&DATE(Dashboard!$B$2,3+1,1)&"")) | E7: =IF($A7="","",SUMIFS(Data!$H$2:$H$25001,Data!$C$2:$C$25001,$A7,Data!$D$2:$D$25001,"Werken",Data!$A$2:$A$25001,">="&DATE(Dashboard!$B$2,4,1)&"",Data!$A$2:$A$25001,"<"&DATE(Dashboard!$B$2,4+1,1)&"")) | F7: =IF($A7="","",SUMIFS(Data!$H$2:$H$25001,Data!$C$2:$C$25001,$A7,Data!$D$2:$D$25001,"Werken",Data!$A$2:$A$25001,">="&DATE(Dashboard!$B$2,5,1)&"",Data!$A$2:$A$25001,"<"&DATE(Dashboard!$B$2,5+1,1)&"")) | G7: =IF($A7="","",SUMIFS(Data!$H$2:$H$25001,Data!$C$2:$C$25001,$A7,Data!$D$2:$D$25001,"Werken",Data!$A$2:$A$25001,">="&DATE(Dashboard!$B$2,6,1)&"",Data!$A$2:$A$25001,"<"&DATE(Dashboard!$B$2,6+1,1)&"")) | H7: =IF($A7="","",SUMIFS(Data!$H$2:$H$25001,Data!$C$2:$C$25001,$A7,Data!$D$2:$D$25001,"Werken",Data!$A$2:$A$25001,">="&DATE(Dashboard!$B$2,7,1)&"",Data!$A$2:$A$25001,"<"&DATE(Dashboard!$B$2,7+1,1)&"")) | I7: =IF($A7="","",SUMIFS(Data!$H$2:$H$25001,Data!$C$2:$C$25001,$A7,Data!$D$2:$D$25001,"Werken",Data!$A$2:$A$25001,">="&DATE(Dashboard!$B$2,8,1)&"",Data!$A$2:$A$25001,"<"&DATE(Dashboard!$B$2,8+1,1)&"")) | J7: =IF($A7="","",SUMIFS(Data!$H$2:$H$25001,Data!$C$2:$C$25001,$A7,Data!$D$2:$D$25001,"Werken",Data!$A$2:$A$25001,">="&DATE(Dashboard!$B$2,9,1)&"",Data!$A$2:$A$25001,"<"&DATE(Dashboard!$B$2,9+1,1)&"")) | K7: =IF($A7="","",SUMIFS(Data!$H$2:$H$25001,Data!$C$2:$C$25001,$A7,Data!$D$2:$D$25001,"Werken",Data!$A$2:$A$25001,">="&DATE(Dashboard!$B$2,10,1)&"",Data!$A$2:$A$25001,"<"&DATE(Dashboard!$B$2,10+1,1)&"")) | L7: =IF($A7="","",SUMIFS(Data!$H$2:$H$25001,Data!$C$2:$C$25001,$A7,Data!$D$2:$D$25001,"Werken",Data!$A$2:$A$25001,">="&DATE(Dashboard!$B$2,11,1)&"",Data!$A$2:$A$25001,"<"&DATE(Dashboard!$B$2,11+1,1)&"")) | M7: =IF($A7="","",SUMIFS(Data!$H$2:$H$25001,Data!$C$2:$C$25001,$A7,Data!$D$2:$D$25001,"Werken",Data!$A$2:$A$25001,">="&DATE(Dashboard!$B$2,12,1)&"",Data!$A$2:$A$25001,"<"&DATE(Dashboard!$B$2,12+1,1)&"")) | N7: =IF($A7="","",SUM(B7:M7)) | P7: =IF(OR($A7="",O7=""),"",N7*O7)
B8: =IF($A8="","",SUMIFS(Data!$H$2:$H$25001,Data!$C$2:$C$25001,$A8,Data!$D$2:$D$25001,"Werken",Data!$A$2:$A$25001,">="&DATE(Dashboard!$B$2,1,1)&"",Data!$A$2:$A$25001,"<"&DATE(Dashboard!$B$2,1+1,1)&"")) | C8: =IF($A8="","",SUMIFS(Data!$H$2:$H$25001,Data!$C$2:$C$25001,$A8,Data!$D$2:$D$25001,"Werken",Data!$A$2:$A$25001,">="&DATE(Dashboard!$B$2,2,1)&"",Data!$A$2:$A$25001,"<"&DATE(Dashboard!$B$2,2+1,1)&"")) | D8: =IF($A8="","",SUMIFS(Data!$H$2:$H$25001,Data!$C$2:$C$25001,$A8,Data!$D$2:$D$25001,"Werken",Data!$A$2:$A$25001,">="&DATE(Dashboard!$B$2,3,1)&"",Data!$A$2:$A$25001,"<"&DATE(Dashboard!$B$2,3+1,1)&"")) | E8: =IF($A8="","",SUMIFS(Data!$H$2:$H$25001,Data!$C$2:$C$25001,$A8,Data!$D$2:$D$25001,"Werken",Data!$A$2:$A$25001,">="&DATE(Dashboard!$B$2,4,1)&"",Data!$A$2:$A$25001,"<"&DATE(Dashboard!$B$2,4+1,1)&"")) | F8: =IF($A8="","",SUMIFS(Data!$H$2:$H$25001,Data!$C$2:$C$25001,$A8,Data!$D$2:$D$25001,"Werken",Data!$A$2:$A$25001,">="&DATE(Dashboard!$B$2,5,1)&"",Data!$A$2:$A$25001,"<"&DATE(Dashboard!$B$2,5+1,1)&"")) | G8: =IF($A8="","",SUMIFS(Data!$H$2:$H$25001,Data!$C$2:$C$25001,$A8,Data!$D$2:$D$25001,"Werken",Data!$A$2:$A$25001,">="&DATE(Dashboard!$B$2,6,1)&"",Data!$A$2:$A$25001,"<"&DATE(Dashboard!$B$2,6+1,1)&"")) | H8: =IF($A8="","",SUMIFS(Data!$H$2:$H$25001,Data!$C$2:$C$25001,$A8,Data!$D$2:$D$25001,"Werken",Data!$A$2:$A$25001,">="&DATE(Dashboard!$B$2,7,1)&"",Data!$A$2:$A$25001,"<"&DATE(Dashboard!$B$2,7+1,1)&"")) | I8: =IF($A8="","",SUMIFS(Data!$H$2:$H$25001,Data!$C$2:$C$25001,$A8,Data!$D$2:$D$25001,"Werken",Data!$A$2:$A$25001,">="&DATE(Dashboard!$B$2,8,1)&"",Data!$A$2:$A$25001,"<"&DATE(Dashboard!$B$2,8+1,1)&"")) | J8: =IF($A8="","",SUMIFS(Data!$H$2:$H$25001,Data!$C$2:$C$25001,$A8,Data!$D$2:$D$25001,"Werken",Data!$A$2:$A$25001,">="&DATE(Dashboard!$B$2,9,1)&"",Data!$A$2:$A$25001,"<"&DATE(Dashboard!$B$2,9+1,1)&"")) | K8: =IF($A8="","",SUMIFS(Data!$H$2:$H$25001,Data!$C$2:$C$25001,$A8,Data!$D$2:$D$25001,"Werken",Data!$A$2:$A$25001,">="&DATE(Dashboard!$B$2,10,1)&"",Data!$A$2:$A$25001,"<"&DATE(Dashboard!$B$2,10+1,1)&"")) | L8: =IF($A8="","",SUMIFS(Data!$H$2:$H$25001,Data!$C$2:$C$25001,$A8,Data!$D$2:$D$25001,"Werken",Data!$A$2:$A$25001,">="&DATE(Dashboard!$B$2,11,1)&"",Data!$A$2:$A$25001,"<"&DATE(Dashboard!$B$2,11+1,1)&"")) | M8: =IF($A8="","",SUMIFS(Data!$H$2:$H$25001,Data!$C$2:$C$25001,$A8,Data!$D$2:$D$25001,"Werken",Data!$A$2:$A$25001,">="&DATE(Dashboard!$B$2,12,1)&"",Data!$A$2:$A$25001,"<"&DATE(Dashboard!$B$2,12+1,1)&"")) | N8: =IF($A8="","",SUM(B8:M8)) | P8: =IF(OR($A8="",O8=""),"",N8*O8)
B9: =IF($A9="","",SUMIFS(Data!$H$2:$H$25001,Data!$C$2:$C$25001,$A9,Data!$D$2:$D$25001,"Werken",Data!$A$2:$A$25001,">="&DATE(Dashboard!$B$2,1,1)&"",Data!$A$2:$A$25001,"<"&DATE(Dashboard!$B$2,1+1,1)&"")) | C9: =IF($A9="","",SUMIFS(Data!$H$2:$H$25001,Data!$C$2:$C$25001,$A9,Data!$D$2:$D$25001,"Werken",Data!$A$2:$A$25001,">="&DATE(Dashboard!$B$2,2,1)&"",Data!$A$2:$A$25001,"<"&DATE(Dashboard!$B$2,2+1,1)&"")) | D9: =IF($A9="","",SUMIFS(Data!$H$2:$H$25001,Data!$C$2:$C$25001,$A9,Data!$D$2:$D$25001,"Werken",Data!$A$2:$A$25001,">="&DATE(Dashboard!$B$2,3,1)&"",Data!$A$2:$A$25001,"<"&DATE(Dashboard!$B$2,3+1,1)&"")) | E9: =IF($A9="","",SUMIFS(Data!$H$2:$H$25001,Data!$C$2:$C$25001,$A9,Data!$D$2:$D$25001,"Werken",Data!$A$2:$A$25001,">="&DATE(Dashboard!$B$2,4,1)&"",Data!$A$2:$A$25001,"<"&DATE(Dashboard!$B$2,4+1,1)&"")) | F9: =IF($A9="","",SUMIFS(Data!$H$2:$H$25001,Data!$C$2:$C$25001,$A9,Data!$D$2:$D$25001,"Werken",Data!$A$2:$A$25001,">="&DATE(Dashboard!$B$2,5,1)&"",Data!$A$2:$A$25001,"<"&DATE(Dashboard!$B$2,5+1,1)&"")) | G9: =IF($A9="","",SUMIFS(Data!$H$2:$H$25001,Data!$C$2:$C$25001,$A9,Data!$D$2:$D$25001,"Werken",Data!$A$2:$A$25001,">="&DATE(Dashboard!$B$2,6,1)&"",Data!$A$2:$A$25001,"<"&DATE(Dashboard!$B$2,6+1,1)&"")) | H9: =IF($A9="","",SUMIFS(Data!$H$2:$H$25001,Data!$C$2:$C$25001,$A9,Data!$D$2:$D$25001,"Werken",Data!$A$2:$A$25001,">="&DATE(Dashboard!$B$2,7,1)&"",Data!$A$2:$A$25001,"<"&DATE(Dashboard!$B$2,7+1,1)&"")) | I9: =IF($A9="","",SUMIFS(Data!$H$2:$H$25001,Data!$C$2:$C$25001,$A9,Data!$D$2:$D$25001,"Werken",Data!$A$2:$A$25001,">="&DATE(Dashboard!$B$2,8,1)&"",Data!$A$2:$A$25001,"<"&DATE(Dashboard!$B$2,8+1,1)&"")) | J9: =IF($A9="","",SUMIFS(Data!$H$2:$H$25001,Data!$C$2:$C$25001,$A9,Data!$D$2:$D$25001,"Werken",Data!$A$2:$A$25001,">="&DATE(Dashboard!$B$2,9,1)&"",Data!$A$2:$A$25001,"<"&DATE(Dashboard!$B$2,9+1,1)&"")) | K9: =IF($A9="","",SUMIFS(Data!$H$2:$H$25001,Data!$C$2:$C$25001,$A9,Data!$D$2:$D$25001,"Werken",Data!$A$2:$A$25001,">="&DATE(Dashboard!$B$2,10,1)&"",Data!$A$2:$A$25001,"<"&DATE(Dashboard!$B$2,10+1,1)&"")) | L9: =IF($A9="","",SUMIFS(Data!$H$2:$H$25001,Data!$C$2:$C$25001,$A9,Data!$D$2:$D$25001,"Werken",Data!$A$2:$A$25001,">="&DATE(Dashboard!$B$2,11,1)&"",Data!$A$2:$A$25001,"<"&DATE(Dashboard!$B$2,11+1,1)&"")) | M9: =IF($A9="","",SUMIFS(Data!$H$2:$H$25001,Data!$C$2:$C$25001,$A9,Data!$D$2:$D$25001,"Werken",Data!$A$2:$A$25001,">="&DATE(Dashboard!$B$2,12,1)&"",Data!$A$2:$A$25001,"<"&DATE(Dashboard!$B$2,12+1,1)&"")) | N9: =IF($A9="","",SUM(B9:M9)) | P9: =IF(OR($A9="",O9=""),"",N9*O9)
B10: =IF($A10="","",SUMIFS(Data!$H$2:$H$25001,Data!$C$2:$C$25001,$A10,Data!$D$2:$D$25001,"Werken",Data!$A$2:$A$25001,">="&DATE(Dashboard!$B$2,1,1)&"",Data!$A$2:$A$25001,"<"&DATE(Dashboard!$B$2,1+1,1)&"")) | C10: =IF($A10="","",SUMIFS(Data!$H$2:$H$25001,Data!$C$2:$C$25001,$A10,Data!$D$2:$D$25001,"Werken",Data!$A$2:$A$25001,">="&DATE(Dashboard!$B$2,2,1)&"",Data!$A$2:$A$25001,"<"&DATE(Dashboard!$B$2,2+1,1)&"")) | D10: =IF($A10="","",SUMIFS(Data!$H$2:$H$25001,Data!$C$2:$C$25001,$A10,Data!$D$2:$D$25001,"Werken",Data!$A$2:$A$25001,">="&DATE(Dashboard!$B$2,3,1)&"",Data!$A$2:$A$25001,"<"&DATE(Dashboard!$B$2,3+1,1)&"")) | E10: =IF($A10="","",SUMIFS(Data!$H$2:$H$25001,Data!$C$2:$C$25001,$A10,Data!$D$2:$D$25001,"Werken",Data!$A$2:$A$25001,">="&DATE(Dashboard!$B$2,4,1)&"",Data!$A$2:$A$25001,"<"&DATE(Dashboard!$B$2,4+1,1)&"")) | F10: =IF($A10="","",SUMIFS(Data!$H$2:$H$25001,Data!$C$2:$C$25001,$A10,Data!$D$2:$D$25001,"Werken",Data!$A$2:$A$25001,">="&DATE(Dashboard!$B$2,5,1)&"",Data!$A$2:$A$25001,"<"&DATE(Dashboard!$B$2,5+1,1)&"")) | G10: =IF($A10="","",SUMIFS(Data!$H$2:$H$25001,Data!$C$2:$C$25001,$A10,Data!$D$2:$D$25001,"Werken",Data!$A$2:$A$25001,">="&DATE(Dashboard!$B$2,6,1)&"",Data!$A$2:$A$25001,"<"&DATE(Dashboard!$B$2,6+1,1)&"")) | H10: =IF($A10="","",SUMIFS(Data!$H$2:$H$25001,Data!$C$2:$C$25001,$A10,Data!$D$2:$D$25001,"Werken",Data!$A$2:$A$25001,">="&DATE(Dashboard!$B$2,7,1)&"",Data!$A$2:$A$25001,"<"&DATE(Dashboard!$B$2,7+1,1)&"")) | I10: =IF($A10="","",SUMIFS(Data!$H$2:$H$25001,Data!$C$2:$C$25001,$A10,Data!$D$2:$D$25001,"Werken",Data!$A$2:$A$25001,">="&DATE(Dashboard!$B$2,8,1)&"",Data!$A$2:$A$25001,"<"&DATE(Dashboard!$B$2,8+1,1)&"")) | J10: =IF($A10="","",SUMIFS(Data!$H$2:$H$25001,Data!$C$2:$C$25001,$A10,Data!$D$2:$D$25001,"Werken",Data!$A$2:$A$25001,">="&DATE(Dashboard!$B$2,9,1)&"",Data!$A$2:$A$25001,"<"&DATE(Dashboard!$B$2,9+1,1)&"")) | K10: =IF($A10="","",SUMIFS(Data!$H$2:$H$25001,Data!$C$2:$C$25001,$A10,Data!$D$2:$D$25001,"Werken",Data!$A$2:$A$25001,">="&DATE(Dashboard!$B$2,10,1)&"",Data!$A$2:$A$25001,"<"&DATE(Dashboard!$B$2,10+1,1)&"")) | L10: =IF($A10="","",SUMIFS(Data!$H$2:$H$25001,Data!$C$2:$C$25001,$A10,Data!$D$2:$D$25001,"Werken",Data!$A$2:$A$25001,">="&DATE(Dashboard!$B$2,11,1)&"",Data!$A$2:$A$25001,"<"&DATE(Dashboard!$B$2,11+1,1)&"")) | M10: =IF($A10="","",SUMIFS(Data!$H$2:$H$25001,Data!$C$2:$C$25001,$A10,Data!$D$2:$D$25001,"Werken",Data!$A$2:$A$25001,">="&DATE(Dashboard!$B$2,12,1)&"",Data!$A$2:$A$25001,"<"&DATE(Dashboard!$B$2,12+1,1)&"")) | N10: =IF($A10="","",SUM(B10:M10)) | P10: =IF(OR($A10="",O10=""),"",N10*O10)
B11: =IF($A11="","",SUMIFS(Data!$H$2:$H$25001,Data!$C$2:$C$25001,$A11,Data!$D$2:$D$25001,"Werken",Data!$A$2:$A$25001,">="&DATE(Dashboard!$B$2,1,1)&"",Data!$A$2:$A$25001,"<"&DATE(Dashboard!$B$2,1+1,1)&"")) | C11: =IF($A11="","",SUMIFS(Data!$H$2:$H$25001,Data!$C$2:$C$25001,$A11,Data!$D$2:$D$25001,"Werken",Data!$A$2:$A$25001,">="&DATE(Dashboard!$B$2,2,1)&"",Data!$A$2:$A$25001,"<"&DATE(Dashboard!$B$2,2+1,1)&"")) | D11: =IF($A11="","",SUMIFS(Data!$H$2:$H$25001,Data!$C$2:$C$25001,$A11,Data!$D$2:$D$25001,"Werken",Data!$A$2:$A$25001,">="&DATE(Dashboard!$B$2,3,1)&"",Data!$A$2:$A$25001,"<"&DATE(Dashboard!$B$2,3+1,1)&"")) | E11: =IF($A11="","",SUMIFS(Data!$H$2:$H$25001,Data!$C$2:$C$25001,$A11,Data!$D$2:$D$25001,"Werken",Data!$A$2:$A$25001,">="&DATE(Dashboard!$B$2,4,1)&"",Data!$A$2:$A$25001,"<"&DATE(Dashboard!$B$2,4+1,1)&"")) | F11: =IF($A11="","",SUMIFS(Data!$H$2:$H$25001,Data!$C$2:$C$25001,$A11,Data!$D$2:$D$25001,"Werken",Data!$A$2:$A$25001,">="&DATE(Dashboard!$B$2,5,1)&"",Data!$A$2:$A$25001,"<"&DATE(Dashboard!$B$2,5+1,1)&"")) | G11: =IF($A11="","",SUMIFS(Data!$H$2:$H$25001,Data!$C$2:$C$25001,$A11,Data!$D$2:$D$25001,"Werken",Data!$A$2:$A$25001,">="&DATE(Dashboard!$B$2,6,1)&"",Data!$A$2:$A$25001,"<"&DATE(Dashboard!$B$2,6+1,1)&"")) | H11: =IF($A11="","",SUMIFS(Data!$H$2:$H$25001,Data!$C$2:$C$25001,$A11,Data!$D$2:$D$25001,"Werken",Data!$A$2:$A$25001,">="&DATE(Dashboard!$B$2,7,1)&"",Data!$A$2:$A$25001,"<"&DATE(Dashboard!$B$2,7+1,1)&"")) | I11: =IF($A11="","",SUMIFS(Data!$H$2:$H$25001,Data!$C$2:$C$25001,$A11,Data!$D$2:$D$25001,"Werken",Data!$A$2:$A$25001,">="&DATE(Dashboard!$B$2,8,1)&"",Data!$A$2:$A$25001,"<"&DATE(Dashboard!$B$2,8+1,1)&"")) | J11: =IF($A11="","",SUMIFS(Data!$H$2:$H$25001,Data!$C$2:$C$25001,$A11,Data!$D$2:$D$25001,"Werken",Data!$A$2:$A$25001,">="&DATE(Dashboard!$B$2,9,1)&"",Data!$A$2:$A$25001,"<"&DATE(Dashboard!$B$2,9+1,1)&"")) | K11: =IF($A11="","",SUMIFS(Data!$H$2:$H$25001,Data!$C$2:$C$25001,$A11,Data!$D$2:$D$25001,"Werken",Data!$A$2:$A$25001,">="&DATE(Dashboard!$B$2,10,1)&"",Data!$A$2:$A$25001,"<"&DATE(Dashboard!$B$2,10+1,1)&"")) | L11: =IF($A11="","",SUMIFS(Data!$H$2:$H$25001,Data!$C$2:$C$25001,$A11,Data!$D$2:$D$25001,"Werken",Data!$A$2:$A$25001,">="&DATE(Dashboard!$B$2,11,1)&"",Data!$A$2:$A$25001,"<"&DATE(Dashboard!$B$2,11+1,1)&"")) | M11: =IF($A11="","",SUMIFS(Data!$H$2:$H$25001,Data!$C$2:$C$25001,$A11,Data!$D$2:$D$25001,"Werken",Data!$A$2:$A$25001,">="&DATE(Dashboard!$B$2,12,1)&"",Data!$A$2:$A$25001,"<"&DATE(Dashboard!$B$2,12+1,1)&"")) | N11: =IF($A11="","",SUM(B11:M11)) | P11: =IF(OR($A11="",O11=""),"",N11*O11)
B12: =IF($A12="","",SUMIFS(Data!$H$2:$H$25001,Data!$C$2:$C$25001,$A12,Data!$D$2:$D$25001,"Werken",Data!$A$2:$A$25001,">="&DATE(Dashboard!$B$2,1,1)&"",Data!$A$2:$A$25001,"<"&DATE(Dashboard!$B$2,1+1,1)&"")) | C12: =IF($A12="","",SUMIFS(Data!$H$2:$H$25001,Data!$C$2:$C$25001,$A12,Data!$D$2:$D$25001,"Werken",Data!$A$2:$A$25001,">="&DATE(Dashboard!$B$2,2,1)&"",Data!$A$2:$A$25001,"<"&DATE(Dashboard!$B$2,2+1,1)&"")) | D12: =IF($A12="","",SUMIFS(Data!$H$2:$H$25001,Data!$C$2:$C$25001,$A12,Data!$D$2:$D$25001,"Werken",Data!$A$2:$A$25001,">="&DATE(Dashboard!$B$2,3,1)&"",Data!$A$2:$A$25001,"<"&DATE(Dashboard!$B$2,3+1,1)&"")) | E12: =IF($A12="","",SUMIFS(Data!$H$2:$H$25001,Data!$C$2:$C$25001,$A12,Data!$D$2:$D$25001,"Werken",Data!$A$2:$A$25001,">="&DATE(Dashboard!$B$2,4,1)&"",Data!$A$2:$A$25001,"<"&DATE(Dashboard!$B$2,4+1,1)&"")) | F12: =IF($A12="","",SUMIFS(Data!$H$2:$H$25001,Data!$C$2:$C$25001,$A12,Data!$D$2:$D$25001,"Werken",Data!$A$2:$A$25001,">="&DATE(Dashboard!$B$2,5,1)&"",Data!$A$2:$A$25001,"<"&DATE(Dashboard!$B$2,5+1,1)&"")) | G12: =IF($A12="","",SUMIFS(Data!$H$2:$H$25001,Data!$C$2:$C$25001,$A12,Data!$D$2:$D$25001,"Werken",Data!$A$2:$A$25001,">="&DATE(Dashboard!$B$2,6,1)&"",Data!$A$2:$A$25001,"<"&DATE(Dashboard!$B$2,6+1,1)&"")) | H12: =IF($A12="","",SUMIFS(Data!$H$2:$H$25001,Data!$C$2:$C$25001,$A12,Data!$D$2:$D$25001,"Werken",Data!$A$2:$A$25001,">="&DATE(Dashboard!$B$2,7,1)&"",Data!$A$2:$A$25001,"<"&DATE(Dashboard!$B$2,7+1,1)&"")) | I12: =IF($A12="","",SUMIFS(Data!$H$2:$H$25001,Data!$C$2:$C$25001,$A12,Data!$D$2:$D$25001,"Werken",Data!$A$2:$A$25001,">="&DATE(Dashboard!$B$2,8,1)&"",Data!$A$2:$A$25001,"<"&DATE(Dashboard!$B$2,8+1,1)&"")) | J12: =IF($A12="","",SUMIFS(Data!$H$2:$H$25001,Data!$C$2:$C$25001,$A12,Data!$D$2:$D$25001,"Werken",Data!$A$2:$A$25001,">="&DATE(Dashboard!$B$2,9,1)&"",Data!$A$2:$A$25001,"<"&DATE(Dashboard!$B$2,9+1,1)&"")) | K12: =IF($A12="","",SUMIFS(Data!$H$2:$H$25001,Data!$C$2:$C$25001,$A12,Data!$D$2:$D$25001,"Werken",Data!$A$2:$A$25001,">="&DATE(Dashboard!$B$2,10,1)&"",Data!$A$2:$A$25001,"<"&DATE(Dashboard!$B$2,10+1,1)&"")) | L12: =IF($A12="","",SUMIFS(Data!$H$2:$H$25001,Data!$C$2:$C$25001,$A12,Data!$D$2:$D$25001,"Werken",Data!$A$2:$A$25001,">="&DATE(Dashboard!$B$2,11,1)&"",Data!$A$2:$A$25001,"<"&DATE(Dashboard!$B$2,11+1,1)&"")) | M12: =IF($A12="","",SUMIFS(Data!$H$2:$H$25001,Data!$C$2:$C$25001,$A12,Data!$D$2:$D$25001,"Werken",Data!$A$2:$A$25001,">="&DATE(Dashboard!$B$2,12,1)&"",Data!$A$2:$A$25001,"<"&DATE(Dashboard!$B$2,12+1,1)&"")) | N12: =IF($A12="","",SUM(B12:M12)) | P12: =IF(OR($A12="",O12=""),"",N12*O12)
B13: =IF($A13="","",SUMIFS(Data!$H$2:$H$25001,Data!$C$2:$C$25001,$A13,Data!$D$2:$D$25001,"Werken",Data!$A$2:$A$25001,">="&DATE(Dashboard!$B$2,1,1)&"",Data!$A$2:$A$25001,"<"&DATE(Dashboard!$B$2,1+1,1)&"")) | C13: =IF($A13="","",SUMIFS(Data!$H$2:$H$25001,Data!$C$2:$C$25001,$A13,Data!$D$2:$D$25001,"Werken",Data!$A$2:$A$25001,">="&DATE(Dashboard!$B$2,2,1)&"",Data!$A$2:$A$25001,"<"&DATE(Dashboard!$B$2,2+1,1)&"")) | D13: =IF($A13="","",SUMIFS(Data!$H$2:$H$25001,Data!$C$2:$C$25001,$A13,Data!$D$2:$D$25001,"Werken",Data!$A$2:$A$25001,">="&DATE(Dashboard!$B$2,3,1)&"",Data!$A$2:$A$25001,"<"&DATE(Dashboard!$B$2,3+1,1)&"")) | E13: =IF($A13="","",SUMIFS(Data!$H$2:$H$25001,Data!$C$2:$C$25001,$A13,Data!$D$2:$D$25001,"Werken",Data!$A$2:$A$25001,">="&DATE(Dashboard!$B$2,4,1)&"",Data!$A$2:$A$25001,"<"&DATE(Dashboard!$B$2,4+1,1)&"")) | F13: =IF($A13="","",SUMIFS(Data!$H$2:$H$25001,Data!$C$2:$C$25001,$A13,Data!$D$2:$D$25001,"Werken",Data!$A$2:$A$25001,">="&DATE(Dashboard!$B$2,5,1)&"",Data!$A$2:$A$25001,"<"&DATE(Dashboard!$B$2,5+1,1)&"")) | G13: =IF($A13="","",SUMIFS(Data!$H$2:$H$25001,Data!$C$2:$C$25001,$A13,Data!$D$2:$D$25001,"Werken",Data!$A$2:$A$25001,">="&DATE(Dashboard!$B$2,6,1)&"",Data!$A$2:$A$25001,"<"&DATE(Dashboard!$B$2,6+1,1)&"")) | H13: =IF($A13="","",SUMIFS(Data!$H$2:$H$25001,Data!$C$2:$C$25001,$A13,Data!$D$2:$D$25001,"Werken",Data!$A$2:$A$25001,">="&DATE(Dashboard!$B$2,7,1)&"",Data!$A$2:$A$25001,"<"&DATE(Dashboard!$B$2,7+1,1)&"")) | I13: =IF($A13="","",SUMIFS(Data!$H$2:$H$25001,Data!$C$2:$C$25001,$A13,Data!$D$2:$D$25001,"Werken",Data!$A$2:$A$25001,">="&DATE(Dashboard!$B$2,8,1)&"",Data!$A$2:$A$25001,"<"&DATE(Dashboard!$B$2,8+1,1)&"")) | J13: =IF($A13="","",SUMIFS(Data!$H$2:$H$25001,Data!$C$2:$C$25001,$A13,Data!$D$2:$D$25001,"Werken",Data!$A$2:$A$25001,">="&DATE(Dashboard!$B$2,9,1)&"",Data!$A$2:$A$25001,"<"&DATE(Dashboard!$B$2,9+1,1)&"")) | K13: =IF($A13="","",SUMIFS(Data!$H$2:$H$25001,Data!$C$2:$C$25001,$A13,Data!$D$2:$D$25001,"Werken",Data!$A$2:$A$25001,">="&DATE(Dashboard!$B$2,10,1)&"",Data!$A$2:$A$25001,"<"&DATE(Dashboard!$B$2,10+1,1)&"")) | L13: =IF($A13="","",SUMIFS(Data!$H$2:$H$25001,Data!$C$2:$C$25001,$A13,Data!$D$2:$D$25001,"Werken",Data!$A$2:$A$25001,">="&DATE(Dashboard!$B$2,11,1)&"",Data!$A$2:$A$25001,"<"&DATE(Dashboard!$B$2,11+1,1)&"")) | M13: =IF($A13="","",SUMIFS(Data!$H$2:$H$25001,Data!$C$2:$C$25001,$A13,Data!$D$2:$D$25001,"Werken",Data!$A$2:$A$25001,">="&DATE(Dashboard!$B$2,12,1)&"",Data!$A$2:$A$25001,"<"&DATE(Dashboard!$B$2,12+1,1)&"")) | N13: =IF($A13="","",SUM(B13:M13)) | P13: =IF(OR($A13="",O13=""),"",N13*O13)
B14: =IF($A14="","",SUMIFS(Data!$H$2:$H$25001,Data!$C$2:$C$25001,$A14,Data!$D$2:$D$25001,"Werken",Data!$A$2:$A$25001,">="&DATE(Dashboard!$B$2,1,1)&"",Data!$A$2:$A$25001,"<"&DATE(Dashboard!$B$2,1+1,1)&"")) | C14: =IF($A14="","",SUMIFS(Data!$H$2:$H$25001,Data!$C$2:$C$25001,$A14,Data!$D$2:$D$25001,"Werken",Data!$A$2:$A$25001,">="&DATE(Dashboard!$B$2,2,1)&"",Data!$A$2:$A$25001,"<"&DATE(Dashboard!$B$2,2+1,1)&"")) | D14: =IF($A14="","",SUMIFS(Data!$H$2:$H$25001,Data!$C$2:$C$25001,$A14,Data!$D$2:$D$25001,"Werken",Data!$A$2:$A$25001,">="&DATE(Dashboard!$B$2,3,1)&"",Data!$A$2:$A$25001,"<"&DATE(Dashboard!$B$2,3+1,1)&"")) | E14: =IF($A14="","",SUMIFS(Data!$H$2:$H$25001,Data!$C$2:$C$25001,$A14,Data!$D$2:$D$25001,"Werken",Data!$A$2:$A$25001,">="&DATE(Dashboard!$B$2,4,1)&"",Data!$A$2:$A$25001,"<"&DATE(Dashboard!$B$2,4+1,1)&"")) | F14: =IF($A14="","",SUMIFS(Data!$H$2:$H$25001,Data!$C$2:$C$25001,$A14,Data!$D$2:$D$25001,"Werken",Data!$A$2:$A$25001,">="&DATE(Dashboard!$B$2,5,1)&"",Data!$A$2:$A$25001,"<"&DATE(Dashboard!$B$2,5+1,1)&"")) | G14: =IF($A14="","",SUMIFS(Data!$H$2:$H$25001,Data!$C$2:$C$25001,$A14,Data!$D$2:$D$25001,"Werken",Data!$A$2:$A$25001,">="&DATE(Dashboard!$B$2,6,1)&"",Data!$A$2:$A$25001,"<"&DATE(Dashboard!$B$2,6+1,1)&"")) | H14: =IF($A14="","",SUMIFS(Data!$H$2:$H$25001,Data!$C$2:$C$25001,$A14,Data!$D$2:$D$25001,"Werken",Data!$A$2:$A$25001,">="&DATE(Dashboard!$B$2,7,1)&"",Data!$A$2:$A$25001,"<"&DATE(Dashboard!$B$2,7+1,1)&"")) | I14: =IF($A14="","",SUMIFS(Data!$H$2:$H$25001,Data!$C$2:$C$25001,$A14,Data!$D$2:$D$25001,"Werken",Data!$A$2:$A$25001,">="&DATE(Dashboard!$B$2,8,1)&"",Data!$A$2:$A$25001,"<"&DATE(Dashboard!$B$2,8+1,1)&"")) | J14: =IF($A14="","",SUMIFS(Data!$H$2:$H$25001,Data!$C$2:$C$25001,$A14,Data!$D$2:$D$25001,"Werken",Data!$A$2:$A$25001,">="&DATE(Dashboard!$B$2,9,1)&"",Data!$A$2:$A$25001,"<"&DATE(Dashboard!$B$2,9+1,1)&"")) | K14: =IF($A14="","",SUMIFS(Data!$H$2:$H$25001,Data!$C$2:$C$25001,$A14,Data!$D$2:$D$25001,"Werken",Data!$A$2:$A$25001,">="&DATE(Dashboard!$B$2,10,1)&"",Data!$A$2:$A$25001,"<"&DATE(Dashboard!$B$2,10+1,1)&"")) | L14: =IF($A14="","",SUMIFS(Data!$H$2:$H$25001,Data!$C$2:$C$25001,$A14,Data!$D$2:$D$25001,"Werken",Data!$A$2:$A$25001,">="&DATE(Dashboard!$B$2,11,1)&"",Data!$A$2:$A$25001,"<"&DATE(Dashboard!$B$2,11+1,1)&"")) | M14: =IF($A14="","",SUMIFS(Data!$H$2:$H$25001,Data!$C$2:$C$25001,$A14,Data!$D$2:$D$25001,"Werken",Data!$A$2:$A$25001,">="&DATE(Dashboard!$B$2,12,1)&"",Data!$A$2:$A$25001,"<"&DATE(Dashboard!$B$2,12+1,1)&"")) | N14: =IF($A14="","",SUM(B14:M14)) | P14: =IF(OR($A14="",O14=""),"",N14*O14)
B15: =IF($A15="","",SUMIFS(Data!$H$2:$H$25001,Data!$C$2:$C$25001,$A15,Data!$D$2:$D$25001,"Werken",Data!$A$2:$A$25001,">="&DATE(Dashboard!$B$2,1,1)&"",Data!$A$2:$A$25001,"<"&DATE(Dashboard!$B$2,1+1,1)&"")) | C15: =IF($A15="","",SUMIFS(Data!$H$2:$H$25001,Data!$C$2:$C$25001,$A15,Data!$D$2:$D$25001,"Werken",Data!$A$2:$A$25001,">="&DATE(Dashboard!$B$2,2,1)&"",Data!$A$2:$A$25001,"<"&DATE(Dashboard!$B$2,2+1,1)&"")) | D15: =IF($A15="","",SUMIFS(Data!$H$2:$H$25001,Data!$C$2:$C$25001,$A15,Data!$D$2:$D$25001,"Werken",Data!$A$2:$A$25001,">="&DATE(Dashboard!$B$2,3,1)&"",Data!$A$2:$A$25001,"<"&DATE(Dashboard!$B$2,3+1,1)&"")) | E15: =IF($A15="","",SUMIFS(Data!$H$2:$H$25001,Data!$C$2:$C$25001,$A15,Data!$D$2:$D$25001,"Werken",Data!$A$2:$A$25001,">="&DATE(Dashboard!$B$2,4,1)&"",Data!$A$2:$A$25001,"<"&DATE(Dashboard!$B$2,4+1,1)&"")) | F15: =IF($A15="","",SUMIFS(Data!$H$2:$H$25001,Data!$C$2:$C$25001,$A15,Data!$D$2:$D$25001,"Werken",Data!$A$2:$A$25001,">="&DATE(Dashboard!$B$2,5,1)&"",Data!$A$2:$A$25001,"<"&DATE(Dashboard!$B$2,5+1,1)&"")) | G15: =IF($A15="","",SUMIFS(Data!$H$2:$H$25001,Data!$C$2:$C$25001,$A15,Data!$D$2:$D$25001,"Werken",Data!$A$2:$A$25001,">="&DATE(Dashboard!$B$2,6,1)&"",Data!$A$2:$A$25001,"<"&DATE(Dashboard!$B$2,6+1,1)&"")) | H15: =IF($A15="","",SUMIFS(Data!$H$2:$H$25001,Data!$C$2:$C$25001,$A15,Data!$D$2:$D$25001,"Werken",Data!$A$2:$A$25001,">="&DATE(Dashboard!$B$2,7,1)&"",Data!$A$2:$A$25001,"<"&DATE(Dashboard!$B$2,7+1,1)&"")) | I15: =IF($A15="","",SUMIFS(Data!$H$2:$H$25001,Data!$C$2:$C$25001,$A15,Data!$D$2:$D$25001,"Werken",Data!$A$2:$A$25001,">="&DATE(Dashboard!$B$2,8,1)&"",Data!$A$2:$A$25001,"<"&DATE(Dashboard!$B$2,8+1,1)&"")) | J15: =IF($A15="","",SUMIFS(Data!$H$2:$H$25001,Data!$C$2:$C$25001,$A15,Data!$D$2:$D$25001,"Werken",Data!$A$2:$A$25001,">="&DATE(Dashboard!$B$2,9,1)&"",Data!$A$2:$A$25001,"<"&DATE(Dashboard!$B$2,9+1,1)&"")) | K15: =IF($A15="","",SUMIFS(Data!$H$2:$H$25001,Data!$C$2:$C$25001,$A15,Data!$D$2:$D$25001,"Werken",Data!$A$2:$A$25001,">="&DATE(Dashboard!$B$2,10,1)&"",Data!$A$2:$A$25001,"<"&DATE(Dashboard!$B$2,10+1,1)&"")) | L15: =IF($A15="","",SUMIFS(Data!$H$2:$H$25001,Data!$C$2:$C$25001,$A15,Data!$D$2:$D$25001,"Werken",Data!$A$2:$A$25001,">="&DATE(Dashboard!$B$2,11,1)&"",Data!$A$2:$A$25001,"<"&DATE(Dashboard!$B$2,11+1,1)&"")) | M15: =IF($A15="","",SUMIFS(Data!$H$2:$H$25001,Data!$C$2:$C$25001,$A15,Data!$D$2:$D$25001,"Werken",Data!$A$2:$A$25001,">="&DATE(Dashboard!$B$2,12,1)&"",Data!$A$2:$A$25001,"<"&DATE(Dashboard!$B$2,12+1,1)&"")) | N15: =IF($A15="","",SUM(B15:M15)) | P15: =IF(OR($A15="",O15=""),"",N15*O15)
B16: =IF($A16="","",SUMIFS(Data!$H$2:$H$25001,Data!$C$2:$C$25001,$A16,Data!$D$2:$D$25001,"Werken",Data!$A$2:$A$25001,">="&DATE(Dashboard!$B$2,1,1)&"",Data!$A$2:$A$25001,"<"&DATE(Dashboard!$B$2,1+1,1)&"")) | C16: =IF($A16="","",SUMIFS(Data!$H$2:$H$25001,Data!$C$2:$C$25001,$A16,Data!$D$2:$D$25001,"Werken",Data!$A$2:$A$25001,">="&DATE(Dashboard!$B$2,2,1)&"",Data!$A$2:$A$25001,"<"&DATE(Dashboard!$B$2,2+1,1)&"")) | D16: =IF($A16="","",SUMIFS(Data!$H$2:$H$25001,Data!$C$2:$C$25001,$A16,Data!$D$2:$D$25001,"Werken",Data!$A$2:$A$25001,">="&DATE(Dashboard!$B$2,3,1)&"",Data!$A$2:$A$25001,"<"&DATE(Dashboard!$B$2,3+1,1)&"")) | E16: =IF($A16="","",SUMIFS(Data!$H$2:$H$25001,Data!$C$2:$C$25001,$A16,Data!$D$2:$D$25001,"Werken",Data!$A$2:$A$25001,">="&DATE(Dashboard!$B$2,4,1)&"",Data!$A$2:$A$25001,"<"&DATE(Dashboard!$B$2,4+1,1)&"")) | F16: =IF($A16="","",SUMIFS(Data!$H$2:$H$25001,Data!$C$2:$C$25001,$A16,Data!$D$2:$D$25001,"Werken",Data!$A$2:$A$25001,">="&DATE(Dashboard!$B$2,5,1)&"",Data!$A$2:$A$25001,"<"&DATE(Dashboard!$B$2,5+1,1)&"")) | G16: =IF($A16="","",SUMIFS(Data!$H$2:$H$25001,Data!$C$2:$C$25001,$A16,Data!$D$2:$D$25001,"Werken",Data!$A$2:$A$25001,">="&DATE(Dashboard!$B$2,6,1)&"",Data!$A$2:$A$25001,"<"&DATE(Dashboard!$B$2,6+1,1)&"")) | H16: =IF($A16="","",SUMIFS(Data!$H$2:$H$25001,Data!$C$2:$C$25001,$A16,Data!$D$2:$D$25001,"Werken",Data!$A$2:$A$25001,">="&DATE(Dashboard!$B$2,7,1)&"",Data!$A$2:$A$25001,"<"&DATE(Dashboard!$B$2,7+1,1)&"")) | I16: =IF($A16="","",SUMIFS(Data!$H$2:$H$25001,Data!$C$2:$C$25001,$A16,Data!$D$2:$D$25001,"Werken",Data!$A$2:$A$25001,">="&DATE(Dashboard!$B$2,8,1)&"",Data!$A$2:$A$25001,"<"&DATE(Dashboard!$B$2,8+1,1)&"")) | J16: =IF($A16="","",SUMIFS(Data!$H$2:$H$25001,Data!$C$2:$C$25001,$A16,Data!$D$2:$D$25001,"Werken",Data!$A$2:$A$25001,">="&DATE(Dashboard!$B$2,9,1)&"",Data!$A$2:$A$25001,"<"&DATE(Dashboard!$B$2,9+1,1)&"")) | K16: =IF($A16="","",SUMIFS(Data!$H$2:$H$25001,Data!$C$2:$C$25001,$A16,Data!$D$2:$D$25001,"Werken",Data!$A$2:$A$25001,">="&DATE(Dashboard!$B$2,10,1)&"",Data!$A$2:$A$25001,"<"&DATE(Dashboard!$B$2,10+1,1)&"")) | L16: =IF($A16="","",SUMIFS(Data!$H$2:$H$25001,Data!$C$2:$C$25001,$A16,Data!$D$2:$D$25001,"Werken",Data!$A$2:$A$25001,">="&DATE(Dashboard!$B$2,11,1)&"",Data!$A$2:$A$25001,"<"&DATE(Dashboard!$B$2,11+1,1)&"")) | M16: =IF($A16="","",SUMIFS(Data!$H$2:$H$25001,Data!$C$2:$C$25001,$A16,Data!$D$2:$D$25001,"Werken",Data!$A$2:$A$25001,">="&DATE(Dashboard!$B$2,12,1)&"",Data!$A$2:$A$25001,"<"&DATE(Dashboard!$B$2,12+1,1)&"")) | N16: =IF($A16="","",SUM(B16:M16)) | P16: =IF(OR($A16="",O16=""),"",N16*O16)
B17: =IF($A17="","",SUMIFS(Data!$H$2:$H$25001,Data!$C$2:$C$25001,$A17,Data!$D$2:$D$25001,"Werken",Data!$A$2:$A$25001,">="&DATE(Dashboard!$B$2,1,1)&"",Data!$A$2:$A$25001,"<"&DATE(Dashboard!$B$2,1+1,1)&"")) | C17: =IF($A17="","",SUMIFS(Data!$H$2:$H$25001,Data!$C$2:$C$25001,$A17,Data!$D$2:$D$25001,"Werken",Data!$A$2:$A$25001,">="&DATE(Dashboard!$B$2,2,1)&"",Data!$A$2:$A$25001,"<"&DATE(Dashboard!$B$2,2+1,1)&"")) | D17: =IF($A17="","",SUMIFS(Data!$H$2:$H$25001,Data!$C$2:$C$25001,$A17,Data!$D$2:$D$25001,"Werken",Data!$A$2:$A$25001,">="&DATE(Dashboard!$B$2,3,1)&"",Data!$A$2:$A$25001,"<"&DATE(Dashboard!$B$2,3+1,1)&"")) | E17: =IF($A17="","",SUMIFS(Data!$H$2:$H$25001,Data!$C$2:$C$25001,$A17,Data!$D$2:$D$25001,"Werken",Data!$A$2:$A$25001,">="&DATE(Dashboard!$B$2,4,1)&"",Data!$A$2:$A$25001,"<"&DATE(Dashboard!$B$2,4+1,1)&"")) | F17: =IF($A17="","",SUMIFS(Data!$H$2:$H$25001,Data!$C$2:$C$25001,$A17,Data!$D$2:$D$25001,"Werken",Data!$A$2:$A$25001,">="&DATE(Dashboard!$B$2,5,1)&"",Data!$A$2:$A$25001,"<"&DATE(Dashboard!$B$2,5+1,1)&"")) | G17: =IF($A17="","",SUMIFS(Data!$H$2:$H$25001,Data!$C$2:$C$25001,$A17,Data!$D$2:$D$25001,"Werken",Data!$A$2:$A$25001,">="&DATE(Dashboard!$B$2,6,1)&"",Data!$A$2:$A$25001,"<"&DATE(Dashboard!$B$2,6+1,1)&"")) | H17: =IF($A17="","",SUMIFS(Data!$H$2:$H$25001,Data!$C$2:$C$25001,$A17,Data!$D$2:$D$25001,"Werken",Data!$A$2:$A$25001,">="&DATE(Dashboard!$B$2,7,1)&"",Data!$A$2:$A$25001,"<"&DATE(Dashboard!$B$2,7+1,1)&"")) | I17: =IF($A17="","",SUMIFS(Data!$H$2:$H$25001,Data!$C$2:$C$25001,$A17,Data!$D$2:$D$25001,"Werken",Data!$A$2:$A$25001,">="&DATE(Dashboard!$B$2,8,1)&"",Data!$A$2:$A$25001,"<"&DATE(Dashboard!$B$2,8+1,1)&"")) | J17: =IF($A17="","",SUMIFS(Data!$H$2:$H$25001,Data!$C$2:$C$25001,$A17,Data!$D$2:$D$25001,"Werken",Data!$A$2:$A$25001,">="&DATE(Dashboard!$B$2,9,1)&"",Data!$A$2:$A$25001,"<"&DATE(Dashboard!$B$2,9+1,1)&"")) | K17: =IF($A17="","",SUMIFS(Data!$H$2:$H$25001,Data!$C$2:$C$25001,$A17,Data!$D$2:$D$25001,"Werken",Data!$A$2:$A$25001,">="&DATE(Dashboard!$B$2,10,1)&"",Data!$A$2:$A$25001,"<"&DATE(Dashboard!$B$2,10+1,1)&"")) | L17: =IF($A17="","",SUMIFS(Data!$H$2:$H$25001,Data!$C$2:$C$25001,$A17,Data!$D$2:$D$25001,"Werken",Data!$A$2:$A$25001,">="&DATE(Dashboard!$B$2,11,1)&"",Data!$A$2:$A$25001,"<"&DATE(Dashboard!$B$2,11+1,1)&"")) | M17: =IF($A17="","",SUMIFS(Data!$H$2:$H$25001,Data!$C$2:$C$25001,$A17,Data!$D$2:$D$25001,"Werken",Data!$A$2:$A$25001,">="&DATE(Dashboard!$B$2,12,1)&"",Data!$A$2:$A$25001,"<"&DATE(Dashboard!$B$2,12+1,1)&"")) | N17: =IF($A17="","",SUM(B17:M17)) | P17: =IF(OR($A17="",O17=""),"",N17*O17)
B18: =IF($A18="","",SUMIFS(Data!$H$2:$H$25001,Data!$C$2:$C$25001,$A18,Data!$D$2:$D$25001,"Werken",Data!$A$2:$A$25001,">="&DATE(Dashboard!$B$2,1,1)&"",Data!$A$2:$A$25001,"<"&DATE(Dashboard!$B$2,1+1,1)&"")) | C18: =IF($A18="","",SUMIFS(Data!$H$2:$H$25001,Data!$C$2:$C$25001,$A18,Data!$D$2:$D$25001,"Werken",Data!$A$2:$A$25001,">="&DATE(Dashboard!$B$2,2,1)&"",Data!$A$2:$A$25001,"<"&DATE(Dashboard!$B$2,2+1,1)&"")) | D18: =IF($A18="","",SUMIFS(Data!$H$2:$H$25001,Data!$C$2:$C$25001,$A18,Data!$D$2:$D$25001,"Werken",Data!$A$2:$A$25001,">="&DATE(Dashboard!$B$2,3,1)&"",Data!$A$2:$A$25001,"<"&DATE(Dashboard!$B$2,3+1,1)&"")) | E18: =IF($A18="","",SUMIFS(Data!$H$2:$H$25001,Data!$C$2:$C$25001,$A18,Data!$D$2:$D$25001,"Werken",Data!$A$2:$A$25001,">="&DATE(Dashboard!$B$2,4,1)&"",Data!$A$2:$A$25001,"<"&DATE(Dashboard!$B$2,4+1,1)&"")) | F18: =IF($A18="","",SUMIFS(Data!$H$2:$H$25001,Data!$C$2:$C$25001,$A18,Data!$D$2:$D$25001,"Werken",Data!$A$2:$A$25001,">="&DATE(Dashboard!$B$2,5,1)&"",Data!$A$2:$A$25001,"<"&DATE(Dashboard!$B$2,5+1,1)&"")) | G18: =IF($A18="","",SUMIFS(Data!$H$2:$H$25001,Data!$C$2:$C$25001,$A18,Data!$D$2:$D$25001,"Werken",Data!$A$2:$A$25001,">="&DATE(Dashboard!$B$2,6,1)&"",Data!$A$2:$A$25001,"<"&DATE(Dashboard!$B$2,6+1,1)&"")) | H18: =IF($A18="","",SUMIFS(Data!$H$2:$H$25001,Data!$C$2:$C$25001,$A18,Data!$D$2:$D$25001,"Werken",Data!$A$2:$A$25001,">="&DATE(Dashboard!$B$2,7,1)&"",Data!$A$2:$A$25001,"<"&DATE(Dashboard!$B$2,7+1,1)&"")) | I18: =IF($A18="","",SUMIFS(Data!$H$2:$H$25001,Data!$C$2:$C$25001,$A18,Data!$D$2:$D$25001,"Werken",Data!$A$2:$A$25001,">="&DATE(Dashboard!$B$2,8,1)&"",Data!$A$2:$A$25001,"<"&DATE(Dashboard!$B$2,8+1,1)&"")) | J18: =IF($A18="","",SUMIFS(Data!$H$2:$H$25001,Data!$C$2:$C$25001,$A18,Data!$D$2:$D$25001,"Werken",Data!$A$2:$A$25001,">="&DATE(Dashboard!$B$2,9,1)&"",Data!$A$2:$A$25001,"<"&DATE(Dashboard!$B$2,9+1,1)&"")) | K18: =IF($A18="","",SUMIFS(Data!$H$2:$H$25001,Data!$C$2:$C$25001,$A18,Data!$D$2:$D$25001,"Werken",Data!$A$2:$A$25001,">="&DATE(Dashboard!$B$2,10,1)&"",Data!$A$2:$A$25001,"<"&DATE(Dashboard!$B$2,10+1,1)&"")) | L18: =IF($A18="","",SUMIFS(Data!$H$2:$H$25001,Data!$C$2:$C$25001,$A18,Data!$D$2:$D$25001,"Werken",Data!$A$2:$A$25001,">="&DATE(Dashboard!$B$2,11,1)&"",Data!$A$2:$A$25001,"<"&DATE(Dashboard!$B$2,11+1,1)&"")) | M18: =IF($A18="","",SUMIFS(Data!$H$2:$H$25001,Data!$C$2:$C$25001,$A18,Data!$D$2:$D$25001,"Werken",Data!$A$2:$A$25001,">="&DATE(Dashboard!$B$2,12,1)&"",Data!$A$2:$A$25001,"<"&DATE(Dashboard!$B$2,12+1,1)&"")) | N18: =IF($A18="","",SUM(B18:M18)) | P18: =IF(OR($A18="",O18=""),"",N18*O18)
... B156: =IF($A156="","",SUMIFS(Data!$H$2:$H$25001,Data!$C$2:$C$25001,$A156,Data!$D$2:$D$25001,"Werken",Data!$A$2:$A$25001,">="&DATE(Dashboard!$B$2,1,1)&"",Data!$A$2:$A$25001,"<"&DATE(Dashboard!$B$2,1+1,1)&"")) | C156: =IF($A156="","",SUMIFS(Data!$H$2:$H$25001,Data!$C$2:$C$25001,$A156,Data!$D$2:$D$25001,"Werken",Data!$A$2:$A$25001,">="&DATE(Dashboard!$B$2,2,1)&"",Data!$A$2:$A$25001,"<"&DATE(Dashboard!$B$2,2+1,1)&"")) | D156: =IF($A156="","",SUMIFS(Data!$H$2:$H$25001,Data!$C$2:$C$25001,$A156,Data!$D$2:$D$25001,"Werken",Data!$A$2:$A$25001,">="&DATE(Dashboard!$B$2,3,1)&"",Data!$A$2:$A$25001,"<"&DATE(Dashboard!$B$2,3+1,1)&"")) | E156: =IF($A156="","",SUMIFS(Data!$H$2:$H$25001,Data!$C$2:$C$25001,$A156,Data!$D$2:$D$25001,"Werken",Data!$A$2:$A$25001,">="&DATE(Dashboard!$B$2,4,1)&"",Data!$A$2:$A$25001,"<"&DATE(Dashboard!$B$2,4+1,1)&"")) | F156: =IF($A156="","",SUMIFS(Data!$H$2:$H$25001,Data!$C$2:$C$25001,$A156,Data!$D$2:$D$25001,"Werken",Data!$A$2:$A$25001,">="&DATE(Dashboard!$B$2,5,1)&"",Data!$A$2:$A$25001,"<"&DATE(Dashboard!$B$2,5+1,1)&"")) | G156: =IF($A156="","",SUMIFS(Data!$H$2:$H$25001,Data!$C$2:$C$25001,$A156,Data!$D$2:$D$25001,"Werken",Data!$A$2:$A$25001,">="&DATE(Dashboard!$B$2,6,1)&"",Data!$A$2:$A$25001,"<"&DATE(Dashboard!$B$2,6+1,1)&"")) | H156: =IF($A156="","",SUMIFS(Data!$H$2:$H$25001,Data!$C$2:$C$25001,$A156,Data!$D$2:$D$25001,"Werken",Data!$A$2:$A$25001,">="&DATE(Dashboard!$B$2,7,1)&"",Data!$A$2:$A$25001,"<"&DATE(Dashboard!$B$2,7+1,1)&"")) | I156: =IF($A156="","",SUMIFS(Data!$H$2:$H$25001,Data!$C$2:$C$25001,$A156,Data!$D$2:$D$25001,"Werken",Data!$A$2:$A$25001,">="&DATE(Dashboard!$B$2,8,1)&"",Data!$A$2:$A$25001,"<"&DATE(Dashboard!$B$2,8+1,1)&"")) | J156: =IF($A156="","",SUMIFS(Data!$H$2:$H$25001,Data!$C$2:$C$25001,$A156,Data!$D$2:$D$25001,"Werken",Data!$A$2:$A$25001,">="&DATE(Dashboard!$B$2,9,1)&"",Data!$A$2:$A$25001,"<"&DATE(Dashboard!$B$2,9+1,1)&"")) | K156: =IF($A156="","",SUMIFS(Data!$H$2:$H$25001,Data!$C$2:$C$25001,$A156,Data!$D$2:$D$25001,"Werken",Data!$A$2:$A$25001,">="&DATE(Dashboard!$B$2,10,1)&"",Data!$A$2:$A$25001,"<"&DATE(Dashboard!$B$2,10+1,1)&"")) | L156: =IF($A156="","",SUMIFS(Data!$H$2:$H$25001,Data!$C$2:$C$25001,$A156,Data!$D$2:$D$25001,"Werken",Data!$A$2:$A$25001,">="&DATE(Dashboard!$B$2,11,1)&"",Data!$A$2:$A$25001,"<"&DATE(Dashboard!$B$2,11+1,1)&"")) | M156: =IF($A156="","",SUMIFS(Data!$H$2:$H$25001,Data!$C$2:$C$25001,$A156,Data!$D$2:$D$25001,"Werken",Data!$A$2:$A$25001,">="&DATE(Dashboard!$B$2,12,1)&"",Data!$A$2:$A$25001,"<"&DATE(Dashboard!$B$2,12+1,1)&"")) | N156: =IF($A156="","",SUM(B156:M156)) | P156: =IF(OR($A156="",O156=""),"",N156*O156)
A157: Totaal | B157: =SUM(B7:B156) | C157: =SUM(C7:C156) | D157: =SUM(D7:D156) | E157: =SUM(E7:E156) | F157: =SUM(F7:F156) | G157: =SUM(G7:G156) | H157: =SUM(H7:H156) | I157: =SUM(I7:I156) | ... N157: =SUM(N7:N156) | P157: =SUM(P7:P156)

Sheet Medewerker x maand
A1: Geregistreerde uren per medewerker per maand
A2: Alle segmenten samen. Rechts per jaar: factureerbaar, reistijd en het percentage factureerbaar.
A6: Medewerker | B6: jan | C6: feb | D6: mrt | E6: apr | F6: mei | G6: jun | H6: jul | I6: aug | J6: sep | K6: okt | L6: nov | M6: dec | N6: Jaar | O6: wv. factureerbaar | P6: wv. reistijd | Q6: % factureerbaar
B7: =IF($A7="","",SUMIFS(Data!$H$2:$H$25001,Data!$B$2:$B$25001,$A7,Data!$A$2:$A$25001,">="&DATE(Dashboard!$B$2,1,1)&"",Data!$A$2:$A$25001,"<"&DATE(Dashboard!$B$2,1+1,1)&"")) | C7: =IF($A7="","",SUMIFS(Data!$H$2:$H$25001,Data!$B$2:$B$25001,$A7,Data!$A$2:$A$25001,">="&DATE(Dashboard!$B$2,2,1)&"",Data!$A$2:$A$25001,"<"&DATE(Dashboard!$B$2,2+1,1)&"")) | D7: =IF($A7="","",SUMIFS(Data!$H$2:$H$25001,Data!$B$2:$B$25001,$A7,Data!$A$2:$A$25001,">="&DATE(Dashboard!$B$2,3,1)&"",Data!$A$2:$A$25001,"<"&DATE(Dashboard!$B$2,3+1,1)&"")) | E7: =IF($A7="","",SUMIFS(Data!$H$2:$H$25001,Data!$B$2:$B$25001,$A7,Data!$A$2:$A$25001,">="&DATE(Dashboard!$B$2,4,1)&"",Data!$A$2:$A$25001,"<"&DATE(Dashboard!$B$2,4+1,1)&"")) | F7: =IF($A7="","",SUMIFS(Data!$H$2:$H$25001,Data!$B$2:$B$25001,$A7,Data!$A$2:$A$25001,">="&DATE(Dashboard!$B$2,5,1)&"",Data!$A$2:$A$25001,"<"&DATE(Dashboard!$B$2,5+1,1)&"")) | G7: =IF($A7="","",SUMIFS(Data!$H$2:$H$25001,Data!$B$2:$B$25001,$A7,Data!$A$2:$A$25001,">="&DATE(Dashboard!$B$2,6,1)&"",Data!$A$2:$A$25001,"<"&DATE(Dashboard!$B$2,6+1,1)&"")) | H7: =IF($A7="","",SUMIFS(Data!$H$2:$H$25001,Data!$B$2:$B$25001,$A7,Data!$A$2:$A$25001,">="&DATE(Dashboard!$B$2,7,1)&"",Data!$A$2:$A$25001,"<"&DATE(Dashboard!$B$2,7+1,1)&"")) | I7: =IF($A7="","",SUMIFS(Data!$H$2:$H$25001,Data!$B$2:$B$25001,$A7,Data!$A$2:$A$25001,">="&DATE(Dashboard!$B$2,8,1)&"",Data!$A$2:$A$25001,"<"&DATE(Dashboard!$B$2,8+1,1)&"")) | J7: =IF($A7="","",SUMIFS(Data!$H$2:$H$25001,Data!$B$2:$B$25001,$A7,Data!$A$2:$A$25001,">="&DATE(Dashboard!$B$2,9,1)&"",Data!$A$2:$A$25001,"<"&DATE(Dashboard!$B$2,9+1,1)&"")) | K7: =IF($A7="","",SUMIFS(Data!$H$2:$H$25001,Data!$B$2:$B$25001,$A7,Data!$A$2:$A$25001,">="&DATE(Dashboard!$B$2,10,1)&"",Data!$A$2:$A$25001,"<"&DATE(Dashboard!$B$2,10+1,1)&"")) | L7: =IF($A7="","",SUMIFS(Data!$H$2:$H$25001,Data!$B$2:$B$25001,$A7,Data!$A$2:$A$25001,">="&DATE(Dashboard!$B$2,11,1)&"",Data!$A$2:$A$25001,"<"&DATE(Dashboard!$B$2,11+1,1)&"")) | M7: =IF($A7="","",SUMIFS(Data!$H$2:$H$25001,Data!$B$2:$B$25001,$A7,Data!$A$2:$A$25001,">="&DATE(Dashboard!$B$2,12,1)&"",Data!$A$2:$A$25001,"<"&DATE(Dashboard!$B$2,12+1,1)&"")) | N7: =IF($A7="","",SUM(B7:M7)) | O7: =IF($A7="","",SUMIFS(Data!$H$2:$H$25001,Data!$B$2:$B$25001,$A7,Data!$D$2:$D$25001,"Werken",Data!$A$2:$A$25001,">="&DATE(Dashboard!$B$2,1,1)&"",Data!$A$2:$A$25001,"<"&DATE(Dashboard!$B$2+1,1,1)&"")) | P7: =IF($A7="","",SUMIFS(Data!$H$2:$H$25001,Data!$B$2:$B$25001,$A7,Data!$D$2:$D$25001,"Reistijd",Data!$A$2:$A$25001,">="&DATE(Dashboard!$B$2,1,1)&"",Data!$A$2:$A$25001,"<"&DATE(Dashboard!$B$2+1,1,1)&"")) | Q7: =IF(OR($A7="",N7=0),"",O7/N7)
B8: =IF($A8="","",SUMIFS(Data!$H$2:$H$25001,Data!$B$2:$B$25001,$A8,Data!$A$2:$A$25001,">="&DATE(Dashboard!$B$2,1,1)&"",Data!$A$2:$A$25001,"<"&DATE(Dashboard!$B$2,1+1,1)&"")) | C8: =IF($A8="","",SUMIFS(Data!$H$2:$H$25001,Data!$B$2:$B$25001,$A8,Data!$A$2:$A$25001,">="&DATE(Dashboard!$B$2,2,1)&"",Data!$A$2:$A$25001,"<"&DATE(Dashboard!$B$2,2+1,1)&"")) | D8: =IF($A8="","",SUMIFS(Data!$H$2:$H$25001,Data!$B$2:$B$25001,$A8,Data!$A$2:$A$25001,">="&DATE(Dashboard!$B$2,3,1)&"",Data!$A$2:$A$25001,"<"&DATE(Dashboard!$B$2,3+1,1)&"")) | E8: =IF($A8="","",SUMIFS(Data!$H$2:$H$25001,Data!$B$2:$B$25001,$A8,Data!$A$2:$A$25001,">="&DATE(Dashboard!$B$2,4,1)&"",Data!$A$2:$A$25001,"<"&DATE(Dashboard!$B$2,4+1,1)&"")) | F8: =IF($A8="","",SUMIFS(Data!$H$2:$H$25001,Data!$B$2:$B$25001,$A8,Data!$A$2:$A$25001,">="&DATE(Dashboard!$B$2,5,1)&"",Data!$A$2:$A$25001,"<"&DATE(Dashboard!$B$2,5+1,1)&"")) | G8: =IF($A8="","",SUMIFS(Data!$H$2:$H$25001,Data!$B$2:$B$25001,$A8,Data!$A$2:$A$25001,">="&DATE(Dashboard!$B$2,6,1)&"",Data!$A$2:$A$25001,"<"&DATE(Dashboard!$B$2,6+1,1)&"")) | H8: =IF($A8="","",SUMIFS(Data!$H$2:$H$25001,Data!$B$2:$B$25001,$A8,Data!$A$2:$A$25001,">="&DATE(Dashboard!$B$2,7,1)&"",Data!$A$2:$A$25001,"<"&DATE(Dashboard!$B$2,7+1,1)&"")) | I8: =IF($A8="","",SUMIFS(Data!$H$2:$H$25001,Data!$B$2:$B$25001,$A8,Data!$A$2:$A$25001,">="&DATE(Dashboard!$B$2,8,1)&"",Data!$A$2:$A$25001,"<"&DATE(Dashboard!$B$2,8+1,1)&"")) | J8: =IF($A8="","",SUMIFS(Data!$H$2:$H$25001,Data!$B$2:$B$25001,$A8,Data!$A$2:$A$25001,">="&DATE(Dashboard!$B$2,9,1)&"",Data!$A$2:$A$25001,"<"&DATE(Dashboard!$B$2,9+1,1)&"")) | K8: =IF($A8="","",SUMIFS(Data!$H$2:$H$25001,Data!$B$2:$B$25001,$A8,Data!$A$2:$A$25001,">="&DATE(Dashboard!$B$2,10,1)&"",Data!$A$2:$A$25001,"<"&DATE(Dashboard!$B$2,10+1,1)&"")) | L8: =IF($A8="","",SUMIFS(Data!$H$2:$H$25001,Data!$B$2:$B$25001,$A8,Data!$A$2:$A$25001,">="&DATE(Dashboard!$B$2,11,1)&"",Data!$A$2:$A$25001,"<"&DATE(Dashboard!$B$2,11+1,1)&"")) | M8: =IF($A8="","",SUMIFS(Data!$H$2:$H$25001,Data!$B$2:$B$25001,$A8,Data!$A$2:$A$25001,">="&DATE(Dashboard!$B$2,12,1)&"",Data!$A$2:$A$25001,"<"&DATE(Dashboard!$B$2,12+1,1)&"")) | N8: =IF($A8="","",SUM(B8:M8)) | O8: =IF($A8="","",SUMIFS(Data!$H$2:$H$25001,Data!$B$2:$B$25001,$A8,Data!$D$2:$D$25001,"Werken",Data!$A$2:$A$25001,">="&DATE(Dashboard!$B$2,1,1)&"",Data!$A$2:$A$25001,"<"&DATE(Dashboard!$B$2+1,1,1)&"")) | P8: =IF($A8="","",SUMIFS(Data!$H$2:$H$25001,Data!$B$2:$B$25001,$A8,Data!$D$2:$D$25001,"Reistijd",Data!$A$2:$A$25001,">="&DATE(Dashboard!$B$2,1,1)&"",Data!$A$2:$A$25001,"<"&DATE(Dashboard!$B$2+1,1,1)&"")) | Q8: =IF(OR($A8="",N8=0),"",O8/N8)
B9: =IF($A9="","",SUMIFS(Data!$H$2:$H$25001,Data!$B$2:$B$25001,$A9,Data!$A$2:$A$25001,">="&DATE(Dashboard!$B$2,1,1)&"",Data!$A$2:$A$25001,"<"&DATE(Dashboard!$B$2,1+1,1)&"")) | C9: =IF($A9="","",SUMIFS(Data!$H$2:$H$25001,Data!$B$2:$B$25001,$A9,Data!$A$2:$A$25001,">="&DATE(Dashboard!$B$2,2,1)&"",Data!$A$2:$A$25001,"<"&DATE(Dashboard!$B$2,2+1,1)&"")) | D9: =IF($A9="","",SUMIFS(Data!$H$2:$H$25001,Data!$B$2:$B$25001,$A9,Data!$A$2:$A$25001,">="&DATE(Dashboard!$B$2,3,1)&"",Data!$A$2:$A$25001,"<"&DATE(Dashboard!$B$2,3+1,1)&"")) | E9: =IF($A9="","",SUMIFS(Data!$H$2:$H$25001,Data!$B$2:$B$25001,$A9,Data!$A$2:$A$25001,">="&DATE(Dashboard!$B$2,4,1)&"",Data!$A$2:$A$25001,"<"&DATE(Dashboard!$B$2,4+1,1)&"")) | F9: =IF($A9="","",SUMIFS(Data!$H$2:$H$25001,Data!$B$2:$B$25001,$A9,Data!$A$2:$A$25001,">="&DATE(Dashboard!$B$2,5,1)&"",Data!$A$2:$A$25001,"<"&DATE(Dashboard!$B$2,5+1,1)&"")) | G9: =IF($A9="","",SUMIFS(Data!$H$2:$H$25001,Data!$B$2:$B$25001,$A9,Data!$A$2:$A$25001,">="&DATE(Dashboard!$B$2,6,1)&"",Data!$A$2:$A$25001,"<"&DATE(Dashboard!$B$2,6+1,1)&"")) | H9: =IF($A9="","",SUMIFS(Data!$H$2:$H$25001,Data!$B$2:$B$25001,$A9,Data!$A$2:$A$25001,">="&DATE(Dashboard!$B$2,7,1)&"",Data!$A$2:$A$25001,"<"&DATE(Dashboard!$B$2,7+1,1)&"")) | I9: =IF($A9="","",SUMIFS(Data!$H$2:$H$25001,Data!$B$2:$B$25001,$A9,Data!$A$2:$A$25001,">="&DATE(Dashboard!$B$2,8,1)&"",Data!$A$2:$A$25001,"<"&DATE(Dashboard!$B$2,8+1,1)&"")) | J9: =IF($A9="","",SUMIFS(Data!$H$2:$H$25001,Data!$B$2:$B$25001,$A9,Data!$A$2:$A$25001,">="&DATE(Dashboard!$B$2,9,1)&"",Data!$A$2:$A$25001,"<"&DATE(Dashboard!$B$2,9+1,1)&"")) | K9: =IF($A9="","",SUMIFS(Data!$H$2:$H$25001,Data!$B$2:$B$25001,$A9,Data!$A$2:$A$25001,">="&DATE(Dashboard!$B$2,10,1)&"",Data!$A$2:$A$25001,"<"&DATE(Dashboard!$B$2,10+1,1)&"")) | L9: =IF($A9="","",SUMIFS(Data!$H$2:$H$25001,Data!$B$2:$B$25001,$A9,Data!$A$2:$A$25001,">="&DATE(Dashboard!$B$2,11,1)&"",Data!$A$2:$A$25001,"<"&DATE(Dashboard!$B$2,11+1,1)&"")) | M9: =IF($A9="","",SUMIFS(Data!$H$2:$H$25001,Data!$B$2:$B$25001,$A9,Data!$A$2:$A$25001,">="&DATE(Dashboard!$B$2,12,1)&"",Data!$A$2:$A$25001,"<"&DATE(Dashboard!$B$2,12+1,1)&"")) | N9: =IF($A9="","",SUM(B9:M9)) | O9: =IF($A9="","",SUMIFS(Data!$H$2:$H$25001,Data!$B$2:$B$25001,$A9,Data!$D$2:$D$25001,"Werken",Data!$A$2:$A$25001,">="&DATE(Dashboard!$B$2,1,1)&"",Data!$A$2:$A$25001,"<"&DATE(Dashboard!$B$2+1,1,1)&"")) | P9: =IF($A9="","",SUMIFS(Data!$H$2:$H$25001,Data!$B$2:$B$25001,$A9,Data!$D$2:$D$25001,"Reistijd",Data!$A$2:$A$25001,">="&DATE(Dashboard!$B$2,1,1)&"",Data!$A$2:$A$25001,"<"&DATE(Dashboard!$B$2+1,1,1)&"")) | Q9: =IF(OR($A9="",N9=0),"",O9/N9)
B10: =IF($A10="","",SUMIFS(Data!$H$2:$H$25001,Data!$B$2:$B$25001,$A10,Data!$A$2:$A$25001,">="&DATE(Dashboard!$B$2,1,1)&"",Data!$A$2:$A$25001,"<"&DATE(Dashboard!$B$2,1+1,1)&"")) | C10: =IF($A10="","",SUMIFS(Data!$H$2:$H$25001,Data!$B$2:$B$25001,$A10,Data!$A$2:$A$25001,">="&DATE(Dashboard!$B$2,2,1)&"",Data!$A$2:$A$25001,"<"&DATE(Dashboard!$B$2,2+1,1)&"")) | D10: =IF($A10="","",SUMIFS(Data!$H$2:$H$25001,Data!$B$2:$B$25001,$A10,Data!$A$2:$A$25001,">="&DATE(Dashboard!$B$2,3,1)&"",Data!$A$2:$A$25001,"<"&DATE(Dashboard!$B$2,3+1,1)&"")) | E10: =IF($A10="","",SUMIFS(Data!$H$2:$H$25001,Data!$B$2:$B$25001,$A10,Data!$A$2:$A$25001,">="&DATE(Dashboard!$B$2,4,1)&"",Data!$A$2:$A$25001,"<"&DATE(Dashboard!$B$2,4+1,1)&"")) | F10: =IF($A10="","",SUMIFS(Data!$H$2:$H$25001,Data!$B$2:$B$25001,$A10,Data!$A$2:$A$25001,">="&DATE(Dashboard!$B$2,5,1)&"",Data!$A$2:$A$25001,"<"&DATE(Dashboard!$B$2,5+1,1)&"")) | G10: =IF($A10="","",SUMIFS(Data!$H$2:$H$25001,Data!$B$2:$B$25001,$A10,Data!$A$2:$A$25001,">="&DATE(Dashboard!$B$2,6,1)&"",Data!$A$2:$A$25001,"<"&DATE(Dashboard!$B$2,6+1,1)&"")) | H10: =IF($A10="","",SUMIFS(Data!$H$2:$H$25001,Data!$B$2:$B$25001,$A10,Data!$A$2:$A$25001,">="&DATE(Dashboard!$B$2,7,1)&"",Data!$A$2:$A$25001,"<"&DATE(Dashboard!$B$2,7+1,1)&"")) | I10: =IF($A10="","",SUMIFS(Data!$H$2:$H$25001,Data!$B$2:$B$25001,$A10,Data!$A$2:$A$25001,">="&DATE(Dashboard!$B$2,8,1)&"",Data!$A$2:$A$25001,"<"&DATE(Dashboard!$B$2,8+1,1)&"")) | J10: =IF($A10="","",SUMIFS(Data!$H$2:$H$25001,Data!$B$2:$B$25001,$A10,Data!$A$2:$A$25001,">="&DATE(Dashboard!$B$2,9,1)&"",Data!$A$2:$A$25001,"<"&DATE(Dashboard!$B$2,9+1,1)&"")) | K10: =IF($A10="","",SUMIFS(Data!$H$2:$H$25001,Data!$B$2:$B$25001,$A10,Data!$A$2:$A$25001,">="&DATE(Dashboard!$B$2,10,1)&"",Data!$A$2:$A$25001,"<"&DATE(Dashboard!$B$2,10+1,1)&"")) | L10: =IF($A10="","",SUMIFS(Data!$H$2:$H$25001,Data!$B$2:$B$25001,$A10,Data!$A$2:$A$25001,">="&DATE(Dashboard!$B$2,11,1)&"",Data!$A$2:$A$25001,"<"&DATE(Dashboard!$B$2,11+1,1)&"")) | M10: =IF($A10="","",SUMIFS(Data!$H$2:$H$25001,Data!$B$2:$B$25001,$A10,Data!$A$2:$A$25001,">="&DATE(Dashboard!$B$2,12,1)&"",Data!$A$2:$A$25001,"<"&DATE(Dashboard!$B$2,12+1,1)&"")) | N10: =IF($A10="","",SUM(B10:M10)) | O10: =IF($A10="","",SUMIFS(Data!$H$2:$H$25001,Data!$B$2:$B$25001,$A10,Data!$D$2:$D$25001,"Werken",Data!$A$2:$A$25001,">="&DATE(Dashboard!$B$2,1,1)&"",Data!$A$2:$A$25001,"<"&DATE(Dashboard!$B$2+1,1,1)&"")) | P10: =IF($A10="","",SUMIFS(Data!$H$2:$H$25001,Data!$B$2:$B$25001,$A10,Data!$D$2:$D$25001,"Reistijd",Data!$A$2:$A$25001,">="&DATE(Dashboard!$B$2,1,1)&"",Data!$A$2:$A$25001,"<"&DATE(Dashboard!$B$2+1,1,1)&"")) | Q10: =IF(OR($A10="",N10=0),"",O10/N10)
B11: =IF($A11="","",SUMIFS(Data!$H$2:$H$25001,Data!$B$2:$B$25001,$A11,Data!$A$2:$A$25001,">="&DATE(Dashboard!$B$2,1,1)&"",Data!$A$2:$A$25001,"<"&DATE(Dashboard!$B$2,1+1,1)&"")) | C11: =IF($A11="","",SUMIFS(Data!$H$2:$H$25001,Data!$B$2:$B$25001,$A11,Data!$A$2:$A$25001,">="&DATE(Dashboard!$B$2,2,1)&"",Data!$A$2:$A$25001,"<"&DATE(Dashboard!$B$2,2+1,1)&"")) | D11: =IF($A11="","",SUMIFS(Data!$H$2:$H$25001,Data!$B$2:$B$25001,$A11,Data!$A$2:$A$25001,">="&DATE(Dashboard!$B$2,3,1)&"",Data!$A$2:$A$25001,"<"&DATE(Dashboard!$B$2,3+1,1)&"")) | E11: =IF($A11="","",SUMIFS(Data!$H$2:$H$25001,Data!$B$2:$B$25001,$A11,Data!$A$2:$A$25001,">="&DATE(Dashboard!$B$2,4,1)&"",Data!$A$2:$A$25001,"<"&DATE(Dashboard!$B$2,4+1,1)&"")) | F11: =IF($A11="","",SUMIFS(Data!$H$2:$H$25001,Data!$B$2:$B$25001,$A11,Data!$A$2:$A$25001,">="&DATE(Dashboard!$B$2,5,1)&"",Data!$A$2:$A$25001,"<"&DATE(Dashboard!$B$2,5+1,1)&"")) | G11: =IF($A11="","",SUMIFS(Data!$H$2:$H$25001,Data!$B$2:$B$25001,$A11,Data!$A$2:$A$25001,">="&DATE(Dashboard!$B$2,6,1)&"",Data!$A$2:$A$25001,"<"&DATE(Dashboard!$B$2,6+1,1)&"")) | H11: =IF($A11="","",SUMIFS(Data!$H$2:$H$25001,Data!$B$2:$B$25001,$A11,Data!$A$2:$A$25001,">="&DATE(Dashboard!$B$2,7,1)&"",Data!$A$2:$A$25001,"<"&DATE(Dashboard!$B$2,7+1,1)&"")) | I11: =IF($A11="","",SUMIFS(Data!$H$2:$H$25001,Data!$B$2:$B$25001,$A11,Data!$A$2:$A$25001,">="&DATE(Dashboard!$B$2,8,1)&"",Data!$A$2:$A$25001,"<"&DATE(Dashboard!$B$2,8+1,1)&"")) | J11: =IF($A11="","",SUMIFS(Data!$H$2:$H$25001,Data!$B$2:$B$25001,$A11,Data!$A$2:$A$25001,">="&DATE(Dashboard!$B$2,9,1)&"",Data!$A$2:$A$25001,"<"&DATE(Dashboard!$B$2,9+1,1)&"")) | K11: =IF($A11="","",SUMIFS(Data!$H$2:$H$25001,Data!$B$2:$B$25001,$A11,Data!$A$2:$A$25001,">="&DATE(Dashboard!$B$2,10,1)&"",Data!$A$2:$A$25001,"<"&DATE(Dashboard!$B$2,10+1,1)&"")) | L11: =IF($A11="","",SUMIFS(Data!$H$2:$H$25001,Data!$B$2:$B$25001,$A11,Data!$A$2:$A$25001,">="&DATE(Dashboard!$B$2,11,1)&"",Data!$A$2:$A$25001,"<"&DATE(Dashboard!$B$2,11+1,1)&"")) | M11: =IF($A11="","",SUMIFS(Data!$H$2:$H$25001,Data!$B$2:$B$25001,$A11,Data!$A$2:$A$25001,">="&DATE(Dashboard!$B$2,12,1)&"",Data!$A$2:$A$25001,"<"&DATE(Dashboard!$B$2,12+1,1)&"")) | N11: =IF($A11="","",SUM(B11:M11)) | O11: =IF($A11="","",SUMIFS(Data!$H$2:$H$25001,Data!$B$2:$B$25001,$A11,Data!$D$2:$D$25001,"Werken",Data!$A$2:$A$25001,">="&DATE(Dashboard!$B$2,1,1)&"",Data!$A$2:$A$25001,"<"&DATE(Dashboard!$B$2+1,1,1)&"")) | P11: =IF($A11="","",SUMIFS(Data!$H$2:$H$25001,Data!$B$2:$B$25001,$A11,Data!$D$2:$D$25001,"Reistijd",Data!$A$2:$A$25001,">="&DATE(Dashboard!$B$2,1,1)&"",Data!$A$2:$A$25001,"<"&DATE(Dashboard!$B$2+1,1,1)&"")) | Q11: =IF(OR($A11="",N11=0),"",O11/N11)
B12: =IF($A12="","",SUMIFS(Data!$H$2:$H$25001,Data!$B$2:$B$25001,$A12,Data!$A$2:$A$25001,">="&DATE(Dashboard!$B$2,1,1)&"",Data!$A$2:$A$25001,"<"&DATE(Dashboard!$B$2,1+1,1)&"")) | C12: =IF($A12="","",SUMIFS(Data!$H$2:$H$25001,Data!$B$2:$B$25001,$A12,Data!$A$2:$A$25001,">="&DATE(Dashboard!$B$2,2,1)&"",Data!$A$2:$A$25001,"<"&DATE(Dashboard!$B$2,2+1,1)&"")) | D12: =IF($A12="","",SUMIFS(Data!$H$2:$H$25001,Data!$B$2:$B$25001,$A12,Data!$A$2:$A$25001,">="&DATE(Dashboard!$B$2,3,1)&"",Data!$A$2:$A$25001,"<"&DATE(Dashboard!$B$2,3+1,1)&"")) | E12: =IF($A12="","",SUMIFS(Data!$H$2:$H$25001,Data!$B$2:$B$25001,$A12,Data!$A$2:$A$25001,">="&DATE(Dashboard!$B$2,4,1)&"",Data!$A$2:$A$25001,"<"&DATE(Dashboard!$B$2,4+1,1)&"")) | F12: =IF($A12="","",SUMIFS(Data!$H$2:$H$25001,Data!$B$2:$B$25001,$A12,Data!$A$2:$A$25001,">="&DATE(Dashboard!$B$2,5,1)&"",Data!$A$2:$A$25001,"<"&DATE(Dashboard!$B$2,5+1,1)&"")) | G12: =IF($A12="","",SUMIFS(Data!$H$2:$H$25001,Data!$B$2:$B$25001,$A12,Data!$A$2:$A$25001,">="&DATE(Dashboard!$B$2,6,1)&"",Data!$A$2:$A$25001,"<"&DATE(Dashboard!$B$2,6+1,1)&"")) | H12: =IF($A12="","",SUMIFS(Data!$H$2:$H$25001,Data!$B$2:$B$25001,$A12,Data!$A$2:$A$25001,">="&DATE(Dashboard!$B$2,7,1)&"",Data!$A$2:$A$25001,"<"&DATE(Dashboard!$B$2,7+1,1)&"")) | I12: =IF($A12="","",SUMIFS(Data!$H$2:$H$25001,Data!$B$2:$B$25001,$A12,Data!$A$2:$A$25001,">="&DATE(Dashboard!$B$2,8,1)&"",Data!$A$2:$A$25001,"<"&DATE(Dashboard!$B$2,8+1,1)&"")) | J12: =IF($A12="","",SUMIFS(Data!$H$2:$H$25001,Data!$B$2:$B$25001,$A12,Data!$A$2:$A$25001,">="&DATE(Dashboard!$B$2,9,1)&"",Data!$A$2:$A$25001,"<"&DATE(Dashboard!$B$2,9+1,1)&"")) | K12: =IF($A12="","",SUMIFS(Data!$H$2:$H$25001,Data!$B$2:$B$25001,$A12,Data!$A$2:$A$25001,">="&DATE(Dashboard!$B$2,10,1)&"",Data!$A$2:$A$25001,"<"&DATE(Dashboard!$B$2,10+1,1)&"")) | L12: =IF($A12="","",SUMIFS(Data!$H$2:$H$25001,Data!$B$2:$B$25001,$A12,Data!$A$2:$A$25001,">="&DATE(Dashboard!$B$2,11,1)&"",Data!$A$2:$A$25001,"<"&DATE(Dashboard!$B$2,11+1,1)&"")) | M12: =IF($A12="","",SUMIFS(Data!$H$2:$H$25001,Data!$B$2:$B$25001,$A12,Data!$A$2:$A$25001,">="&DATE(Dashboard!$B$2,12,1)&"",Data!$A$2:$A$25001,"<"&DATE(Dashboard!$B$2,12+1,1)&"")) | N12: =IF($A12="","",SUM(B12:M12)) | O12: =IF($A12="","",SUMIFS(Data!$H$2:$H$25001,Data!$B$2:$B$25001,$A12,Data!$D$2:$D$25001,"Werken",Data!$A$2:$A$25001,">="&DATE(Dashboard!$B$2,1,1)&"",Data!$A$2:$A$25001,"<"&DATE(Dashboard!$B$2+1,1,1)&"")) | P12: =IF($A12="","",SUMIFS(Data!$H$2:$H$25001,Data!$B$2:$B$25001,$A12,Data!$D$2:$D$25001,"Reistijd",Data!$A$2:$A$25001,">="&DATE(Dashboard!$B$2,1,1)&"",Data!$A$2:$A$25001,"<"&DATE(Dashboard!$B$2+1,1,1)&"")) | Q12: =IF(OR($A12="",N12=0),"",O12/N12)
